File: Datasets/Mendeley/MND_025.csv
[Measurement conditions]
Sample identification,LA05_0R0_0R2a
Comment,
Anode material,Cu
K-Alpha1 wavelength,1.5405980
K-Alpha2 wavelength,1.5444260
Ratio K-Alpha2/K-Alpha1,0.500
Divergence slit,Fixed,0.38mm
Monochromator used,NO
Generator voltage, 45
Tube current, 40
File date and time,03-Apr-2019 14:21
Unit cell,
h k l, 0 0 0
Scan axis,Gonio
Scan range,3.010000000,74.990000000
Scan step size,0.0200000
No. of points, 3599
Scan type,CONTINUOUS
Time per step,10.160
[Scan points]
Angle,Intensity
3.020000000,536.6
3.080000000,492.7
3.140000000,533.8
3.200000000,526.6
3.260000000,519.8
3.320000000,552.0
3.380000000,576.6
3.440000000,601.0
3.500000000,653.8
3.560000000,642.6
3.620000000,623.8
3.680000000,648.4
3.740000000,636.4
3.800000000,698.0
3.860000000,671.6
3.920000000,672.3
3.980000000,675.0
4.040000000,704.7
4.100000000,740.1
4.160000000,743.1
4.220000000,715.1
4.280000000,731.1
4.340000000,723.9
4.400000000,708.7
4.460000000,734.0
4.520000000,728.1
4.580000000,727.5
4.640000000,748.4
4.700000000,733.6
4.760000000,737.9
4.820000000,697.2
4.880000000,721.6
4.940000000,713.9
5.000000000,703.0
5.060000000,732.2
5.120000000,671.0
5.180000000,700.3
5.240000000,688.2
5.300000000,689.7
5.360000000,710.8
5.420000000,692.1
5.480000000,682.3
5.540000000,666.6
5.600000000,658.0
5.660000000,612.2
5.720000000,697.3
5.780000000,654.8
5.840000000,688.0
5.900000000,672.7
5.960000000,605.0
6.020000000,637.7
6.080000000,646.2
6.140000000,661.6
6.200000000,621.7
6.260000000,585.9
6.320000000,662.5
6.380000000,580.6
6.440000000,594.6
6.500000000,638.0
6.560000000,584.6
6.620000000,611.5
6.680000000,612.6
6.740000000,551.2
6.800000000,613.1
6.860000000,612.0
6.920000000,586.5
6.980000000,615.7
7.040000000,557.2
7.100000000,639.3
7.160000000,607.9
7.220000000,588.6
7.280000000,583.1
7.340000000,589.9
7.400000000,599.2
7.460000000,609.7
7.520000000,621.2
7.580000000,624.5
7.640000000,659.2
7.700000000,678.6
7.760000000,694.7
7.820000000,703.4
7.880000000,704.2
7.940000000,759.9
8.000000000,829.8
8.060000000,859.4
8.120000000,919.9
8.180000000,968.1
8.240000000,1098.8
8.300000000,1199.2
8.360000000,1335.2
8.420000000,1464.9
8.480000000,1575.0
8.540000000,1748.8
8.600000000,1889.2
8.660000000,2141.3
8.720000000,2285.5
8.780000000,2493.1
8.840000000,2696.3
8.900000000,2651.5
8.960000000,2189.9
9.020000000,1937.3
9.080000000,1543.3
9.140000000,1262.0
9.200000000,1035.9
9.260000000,941.0
9.320000000,764.7
9.380000000,715.3
9.440000000,635.4
9.500000000,598.1
9.560000000,583.6
9.620000000,537.0
9.680000000,480.1
9.740000000,509.6
9.800000000,475.8
9.860000000,488.0
9.920000000,484.9
9.980000000,470.1
10.040000000,425.7
10.100000000,496.9
10.160000000,463.4
10.220000000,506.8
10.280000000,483.5
10.340000000,476.3
10.400000000,459.5
10.460000000,512.2
10.520000000,456.0
10.580000000,486.5
10.640000000,511.3
10.700000000,502.7
10.760000000,536.0
10.820000000,529.0
10.880000000,565.1
10.940000000,552.3
11.000000000,565.8
11.060000000,584.5
11.120000000,575.0
11.180000000,600.2
11.240000000,617.9
11.300000000,641.5
11.360000000,630.4
11.420000000,670.1
11.480000000,703.3
11.540000000,692.3
11.600000000,722.5
11.660000000,777.1
11.720000000,825.8
11.780000000,860.8
11.840000000,843.7
11.900000000,934.6
11.960000000,965.6
12.020000000,1048.1
12.080000000,1039.1
12.140000000,1030.7
12.200000000,1092.1
12.260000000,1087.8
12.320000000,1095.1
12.380000000,1085.1
12.440000000,1022.1
12.500000000,970.0
12.560000000,850.2
12.620000000,795.0
12.680000000,740.0
12.740000000,636.0
12.800000000,547.9
12.860000000,551.2
12.920000000,526.1
12.980000000,459.5
13.040000000,383.3
13.100000000,383.5
13.160000000,365.2
13.220000000,333.7
13.280000000,353.9
13.340000000,295.6
13.400000000,283.8
13.460000000,291.4
13.520000000,264.2
13.580000000,261.3
13.640000000,255.8
13.700000000,248.5
13.760000000,269.6
13.820000000,257.9
13.880000000,239.1
13.940000000,250.2
14.000000000,233.1
14.060000000,227.6
14.120000000,248.0
14.180000000,209.1
14.240000000,200.0
14.300000000,222.9
14.360000000,197.5
14.420000000,216.5
14.480000000,215.5
14.540000000,191.8
14.600000000,227.0
14.660000000,222.4
14.720000000,215.3
14.780000000,207.9
14.840000000,208.4
14.900000000,213.3
14.960000000,189.5
15.020000000,218.1
15.080000000,199.9
15.140000000,192.3
15.200000000,211.1
15.260000000,201.4
15.320000000,222.6
15.380000000,231.7
15.440000000,192.2
15.500000000,212.0
15.560000000,204.9
15.620000000,211.3
15.680000000,228.3
15.740000000,183.0
15.800000000,191.8
15.860000000,192.2
15.920000000,213.8
15.980000000,166.2
16.040000000,205.8
16.100000000,198.6
16.160000000,216.9
16.220000000,205.0
16.280000000,224.3
16.340000000,166.7
16.400000000,223.3
16.460000000,220.0
16.520000000,228.2
16.580000000,227.2
16.640000000,229.6
16.700000000,242.9
16.760000000,222.9
16.820000000,224.2
16.880000000,231.6
16.940000000,239.0
17.000000000,260.6
17.060000000,280.4
17.120000000,244.4
17.180000000,265.9
17.240000000,336.0
17.300000000,331.0
17.360000000,407.5
17.420000000,403.7
17.480000000,456.7
17.540000000,529.3
17.600000000,622.9
17.660000000,707.2
17.720000000,838.0
17.780000000,930.2
17.840000000,928.1
17.900000000,814.5
17.960000000,718.2
18.020000000,584.3
18.080000000,533.3
18.140000000,458.8
18.200000000,415.8
18.260000000,323.9
18.320000000,295.3
18.380000000,309.3
18.440000000,268.8
18.500000000,260.5
18.560000000,260.4
18.620000000,213.9
18.680000000,215.9
18.740000000,249.8
18.800000000,224.4
18.860000000,204.7
18.920000000,222.4
18.980000000,181.5
19.040000000,222.7
19.100000000,209.6
19.160000000,204.2
19.220000000,198.0
19.280000000,211.4
19.340000000,238.5
19.400000000,206.5
19.460000000,193.6
19.520000000,238.2
19.580000000,237.6
19.640000000,285.4
19.700000000,375.8
19.760000000,504.0
19.820000000,639.7
19.880000000,709.5
19.940000000,640.4
20.000000000,637.4
20.060000000,524.8
20.120000000,444.7
20.180000000,431.3
20.240000000,367.2
20.300000000,369.8
20.360000000,361.9
20.420000000,391.8
20.480000000,382.5
20.540000000,384.3
20.600000000,316.9
20.660000000,307.3
20.720000000,351.1
20.780000000,366.5
20.840000000,436.4
20.900000000,530.8
20.960000000,525.8
21.020000000,392.0
21.080000000,330.7
21.140000000,310.2
21.200000000,301.5
21.260000000,332.5
21.320000000,354.6
21.380000000,327.8
21.440000000,323.1
21.500000000,300.2
21.560000000,319.8
21.620000000,306.4
21.680000000,280.6
21.740000000,290.2
21.800000000,299.7
21.860000000,307.4
21.920000000,286.4
21.980000000,276.7
22.040000000,278.6
22.100000000,291.5
22.160000000,288.3
22.220000000,288.3
22.280000000,264.9
22.340000000,298.5
22.400000000,305.0
22.460000000,316.8
22.520000000,293.4
22.580000000,302.2
22.640000000,355.8
22.700000000,323.2
22.760000000,324.0
22.820000000,371.5
22.880000000,336.7
22.940000000,395.3
23.000000000,388.3
23.060000000,370.2
23.120000000,414.8
23.180000000,360.9
23.240000000,366.5
23.300000000,404.9
23.360000000,371.0
23.420000000,370.2
23.480000000,401.6
23.540000000,396.1
23.600000000,375.5
23.660000000,415.7
23.720000000,443.4
23.780000000,434.4
23.840000000,475.4
23.900000000,492.5
23.960000000,528.4
24.020000000,518.2
24.080000000,524.7
24.140000000,545.4
24.200000000,534.7
24.260000000,573.9
24.320000000,623.1
24.380000000,673.0
24.440000000,664.8
24.500000000,739.6
24.560000000,768.5
24.620000000,755.6
24.680000000,775.8
24.740000000,821.0
24.800000000,839.1
24.860000000,798.4
24.920000000,815.6
24.980000000,876.7
25.040000000,799.1
25.100000000,806.6
25.160000000,755.1
25.220000000,761.9
25.280000000,774.9
25.340000000,795.7
25.400000000,818.6
25.460000000,692.7
25.520000000,638.7
25.580000000,590.9
25.640000000,592.1
25.700000000,539.7
25.760000000,527.4
25.820000000,534.9
25.880000000,509.8
25.940000000,512.1
26.000000000,548.9
26.060000000,539.5
26.120000000,574.6
26.180000000,557.4
26.240000000,606.7
26.300000000,730.6
26.360000000,774.0
26.420000000,898.9
26.480000000,1037.4
26.540000000,1312.9
26.600000000,1858.1
26.660000000,2589.9
26.720000000,3162.4
26.780000000,2641.0
26.840000000,2111.6
26.900000000,1667.3
26.960000000,1402.3
27.020000000,1165.4
27.080000000,1039.2
27.140000000,863.3
27.200000000,703.3
27.260000000,633.4
27.320000000,595.4
27.380000000,535.2
27.440000000,527.8
27.500000000,504.2
27.560000000,415.4
27.620000000,482.3
27.680000000,449.2
27.740000000,425.5
27.800000000,420.7
27.860000000,476.3
27.920000000,453.1
27.980000000,416.2
28.040000000,377.0
28.100000000,357.2
28.160000000,367.3
28.220000000,351.2
28.280000000,335.1
28.340000000,361.5
28.400000000,332.7
28.460000000,350.8
28.520000000,321.4
28.580000000,313.9
28.640000000,388.0
28.700000000,329.1
28.760000000,350.3
28.820000000,381.3
28.880000000,320.0
28.940000000,353.7
29.000000000,329.2
29.060000000,373.4
29.120000000,378.0
29.180000000,402.7
29.240000000,371.5
29.300000000,382.8
29.360000000,348.2
29.420000000,366.3
29.480000000,342.2
29.540000000,335.6
29.600000000,328.3
29.660000000,360.5
29.720000000,363.2
29.780000000,338.8
29.840000000,403.8
29.900000000,414.0
29.960000000,354.4
30.020000000,356.9
30.080000000,367.3
30.140000000,336.2
30.200000000,314.7
30.260000000,316.8
30.320000000,305.5
30.380000000,308.1
30.440000000,312.0
30.500000000,302.2
30.560000000,313.5
30.620000000,320.3
30.680000000,288.4
30.740000000,307.6
30.800000000,308.0
30.860000000,292.0
30.920000000,296.3
30.980000000,293.2
31.040000000,287.2
31.100000000,336.5
31.160000000,305.9
31.220000000,331.4
31.280000000,305.2
31.340000000,286.9
31.400000000,303.4
31.460000000,291.8
31.520000000,302.0
31.580000000,286.4
31.640000000,257.4
31.700000000,255.8
31.760000000,290.8
31.820000000,276.7
31.880000000,251.6
31.940000000,280.7
32.000000000,299.3
32.060000000,261.7
32.120000000,266.9
32.180000000,264.1
32.240000000,250.4
32.300000000,233.7
32.360000000,228.8
32.420000000,245.4
32.480000000,236.2
32.540000000,201.2
32.600000000,206.6
32.660000000,227.0
32.720000000,201.4
32.780000000,203.9
32.840000000,186.9
32.900000000,209.5
32.960000000,233.3
33.020000000,231.7
33.080000000,211.1
33.140000000,199.5
33.200000000,226.2
33.260000000,234.8
33.320000000,206.6
33.380000000,200.8
33.440000000,205.7
33.500000000,208.1
33.560000000,232.4
33.620000000,216.9
33.680000000,210.7
33.740000000,214.9
33.800000000,203.7
33.860000000,205.9
33.920000000,192.0
33.980000000,213.8
34.040000000,207.9
34.100000000,204.9
34.160000000,179.4
34.220000000,212.2
34.280000000,174.6
34.340000000,197.4
34.400000000,212.9
34.460000000,244.1
34.520000000,279.1
34.580000000,331.6
34.640000000,396.2
34.700000000,437.1
34.760000000,444.6
34.820000000,480.6
34.880000000,513.7
34.940000000,546.7
35.000000000,606.2
35.060000000,655.6
35.120000000,611.2
35.180000000,533.2
35.240000000,446.0
35.300000000,379.5
35.360000000,358.6
35.420000000,310.9
35.480000000,314.2
35.540000000,327.1
35.600000000,276.9
35.660000000,314.3
35.720000000,335.0
35.780000000,341.8
35.840000000,327.2
35.900000000,366.8
35.960000000,348.6
36.020000000,314.7
36.080000000,339.0
36.140000000,319.8
36.200000000,272.8
36.260000000,286.1
36.320000000,266.8
36.380000000,256.7
36.440000000,272.4
36.500000000,271.8
36.560000000,337.2
36.620000000,350.0
36.680000000,331.4
36.740000000,298.7
36.800000000,292.4
36.860000000,272.8
36.920000000,252.8
36.980000000,260.3
37.040000000,275.7
37.100000000,254.3
37.160000000,238.0
37.220000000,221.8
37.280000000,266.8
37.340000000,259.9
37.400000000,265.4
37.460000000,296.0
37.520000000,316.8
37.580000000,315.7
37.640000000,317.0
37.700000000,315.0
37.760000000,330.5
37.820000000,367.7
37.880000000,357.1
37.940000000,335.9
38.000000000,296.5
38.060000000,286.6
38.120000000,271.6
38.180000000,270.0
38.240000000,277.7
38.300000000,285.2
38.360000000,252.6
38.420000000,257.9
38.480000000,254.4
38.540000000,238.7
38.600000000,239.0
38.660000000,252.6
38.720000000,226.3
38.780000000,212.4
38.840000000,208.5
38.900000000,197.0
38.960000000,191.3
39.020000000,213.5
39.080000000,218.8
39.140000000,234.7
39.200000000,216.7
39.260000000,215.0
39.320000000,203.5
39.380000000,204.2
39.440000000,219.2
39.500000000,230.5
39.560000000,251.8
39.620000000,214.2
39.680000000,192.2
39.740000000,186.5
39.800000000,167.3
39.860000000,172.0
39.920000000,199.1
39.980000000,188.0
40.040000000,195.5
40.100000000,213.3
40.160000000,206.0
40.220000000,194.6
40.280000000,245.1
40.340000000,233.7
40.400000000,222.7
40.460000000,198.6
40.520000000,177.3
40.580000000,200.2
40.640000000,186.7
40.700000000,170.7
40.760000000,188.6
40.820000000,202.7
40.880000000,197.8
40.940000000,190.7
41.000000000,180.6
41.060000000,211.0
41.120000000,198.3
41.180000000,195.5
41.240000000,209.1
41.300000000,191.0
41.360000000,209.1
41.420000000,199.6
41.480000000,179.7
41.540000000,178.3
41.600000000,187.6
41.660000000,196.7
41.720000000,182.0
41.780000000,201.7
41.840000000,186.0
41.900000000,190.2
41.960000000,192.6
42.020000000,206.1
42.080000000,218.2
42.140000000,236.8
42.200000000,220.3
42.260000000,232.4
42.320000000,294.9
42.380000000,261.7
42.440000000,268.3
42.500000000,274.9
42.560000000,242.9
42.620000000,263.6
42.680000000,227.4
42.740000000,205.0
42.800000000,197.0
42.860000000,182.8
42.920000000,209.4
42.980000000,210.0
43.040000000,188.0
43.100000000,165.7
43.160000000,180.4
43.220000000,180.7
43.280000000,174.2
43.340000000,163.8
43.400000000,199.3
43.460000000,179.9
43.520000000,160.7
43.580000000,202.0
43.640000000,187.3
43.700000000,191.6
43.760000000,194.0
43.820000000,193.0
43.880000000,189.8
43.940000000,205.7
44.000000000,205.6
44.060000000,210.8
44.120000000,186.0
44.180000000,186.5
44.240000000,227.8
44.300000000,201.5
44.360000000,207.6
44.420000000,197.5
44.480000000,219.7
44.540000000,220.0
44.600000000,220.7
44.660000000,257.4
44.720000000,271.4
44.780000000,262.2
44.840000000,295.0
44.900000000,308.4
44.960000000,345.6
45.020000000,377.9
45.080000000,429.9
45.140000000,491.2
45.200000000,581.2
45.260000000,671.8
45.320000000,715.4
45.380000000,736.2
45.440000000,777.3
45.500000000,759.1
45.560000000,679.6
45.620000000,588.5
45.680000000,501.6
45.740000000,477.4
45.800000000,422.7
45.860000000,412.5
45.920000000,371.8
45.980000000,338.9
46.040000000,286.5
46.100000000,304.6
46.160000000,259.4
46.220000000,243.3
46.280000000,244.1
46.340000000,258.1
46.400000000,221.6
46.460000000,236.1
46.520000000,224.2
46.580000000,204.1
46.640000000,200.8
46.700000000,206.4
46.760000000,203.8
46.820000000,205.2
46.880000000,183.5
46.940000000,181.4
47.000000000,165.5
47.060000000,167.5
47.120000000,156.6
47.180000000,164.8
47.240000000,162.2
47.300000000,147.3
47.360000000,156.3
47.420000000,163.7
47.480000000,147.3
47.540000000,148.0
47.600000000,159.4
47.660000000,159.0
47.720000000,156.0
47.780000000,158.2
47.840000000,167.8
47.900000000,162.4
47.960000000,153.6
48.020000000,186.2
48.080000000,194.6
48.140000000,171.8
48.200000000,215.4
48.260000000,155.4
48.320000000,156.5
48.380000000,160.4
48.440000000,140.8
48.500000000,151.3
48.560000000,177.8
48.620000000,157.4
48.680000000,126.6
48.740000000,131.1
48.800000000,150.6
48.860000000,139.0
48.920000000,140.1
48.980000000,142.4
49.040000000,143.2
49.100000000,149.2
49.160000000,160.0
49.220000000,142.9
49.280000000,144.9
49.340000000,139.5
49.400000000,148.3
49.460000000,147.3
49.520000000,124.0
49.580000000,162.2
49.640000000,151.7
49.700000000,154.1
49.760000000,138.5
49.820000000,161.5
49.880000000,126.8
49.940000000,141.0
50.000000000,148.7
50.060000000,161.7
50.120000000,214.7
50.180000000,295.7
50.240000000,232.4
50.300000000,217.0
50.360000000,186.4
50.420000000,165.1
50.480000000,152.8
50.540000000,140.4
50.600000000,141.3
50.660000000,164.2
50.720000000,156.7
50.780000000,151.8
50.840000000,145.2
50.900000000,161.0
50.960000000,154.3
51.020000000,169.0
51.080000000,154.2
51.140000000,136.4
51.200000000,142.0
51.260000000,132.8
51.320000000,147.2
51.380000000,157.4
51.440000000,121.3
51.500000000,132.7
51.560000000,141.8
51.620000000,127.8
51.680000000,116.8
51.740000000,134.3
51.800000000,139.4
51.860000000,126.4
51.920000000,128.9
51.980000000,121.4
52.040000000,127.9
52.100000000,132.4
52.160000000,146.6
52.220000000,133.5
52.280000000,135.4
52.340000000,147.0
52.400000000,129.6
52.460000000,145.9
52.520000000,156.8
52.580000000,139.0
52.640000000,137.8
52.700000000,152.7
52.760000000,145.0
52.820000000,160.2
52.880000000,180.4
52.940000000,168.1
53.000000000,165.6
53.060000000,184.7
53.120000000,165.3
53.180000000,160.9
53.240000000,180.5
53.300000000,152.0
53.360000000,171.4
53.420000000,162.0
53.480000000,193.8
53.540000000,167.1
53.600000000,159.1
53.660000000,174.7
53.720000000,182.6
53.780000000,171.8
53.840000000,180.2
53.900000000,187.0
53.960000000,216.9
54.020000000,207.0
54.080000000,197.9
54.140000000,198.6
54.200000000,188.7
54.260000000,193.3
54.320000000,201.1
54.380000000,205.8
54.440000000,209.8
54.500000000,205.1
54.560000000,210.6
54.620000000,206.0
54.680000000,221.9
54.740000000,238.8
54.800000000,223.7
54.860000000,265.2
54.920000000,265.2
54.980000000,260.6
55.040000000,314.5
55.100000000,307.7
55.160000000,278.1
55.220000000,315.6
55.280000000,297.8
55.340000000,277.7
55.400000000,285.0
55.460000000,291.7
55.520000000,285.5
55.580000000,257.2
55.640000000,269.0
55.700000000,271.8
55.760000000,268.4
55.820000000,237.9
55.880000000,293.8
55.940000000,266.0
56.000000000,274.5
56.060000000,264.1
56.120000000,217.1
56.180000000,199.2
56.240000000,223.8
56.300000000,235.0
56.360000000,224.7
56.420000000,215.5
56.480000000,206.1
56.540000000,215.0
56.600000000,206.3
56.660000000,220.7
56.720000000,204.0
56.780000000,197.1
56.840000000,172.7
56.900000000,199.4
56.960000000,171.4
57.020000000,198.4
57.080000000,172.1
57.140000000,187.1
57.200000000,191.6
57.260000000,167.3
57.320000000,172.1
57.380000000,161.0
57.440000000,188.4
57.500000000,146.2
57.560000000,158.8
57.620000000,176.9
57.680000000,158.3
57.740000000,163.3
57.800000000,150.4
57.860000000,154.8
57.920000000,158.6
57.980000000,152.1
58.040000000,155.7
58.100000000,153.4
58.160000000,162.6
58.220000000,158.0
58.280000000,133.8
58.340000000,155.2
58.400000000,126.9
58.460000000,130.8
58.520000000,143.8
58.580000000,142.2
58.640000000,151.1
58.700000000,136.4
58.760000000,152.8
58.820000000,152.8
58.880000000,129.2
58.940000000,159.2
59.000000000,157.1
59.060000000,170.5
59.120000000,150.1
59.180000000,149.6
59.240000000,146.9
59.300000000,169.5
59.360000000,177.4
59.420000000,129.2
59.480000000,175.8
59.540000000,170.0
59.600000000,153.9
59.660000000,179.9
59.720000000,136.7
59.780000000,175.7
59.840000000,184.3
59.900000000,188.8
59.960000000,250.5
60.020000000,246.8
60.080000000,227.5
60.140000000,233.0
60.200000000,204.5
60.260000000,174.4
60.320000000,180.3
60.380000000,181.9
60.440000000,176.5
60.500000000,184.8
60.560000000,177.2
60.620000000,185.6
60.680000000,196.6
60.740000000,177.5
60.800000000,167.5
60.860000000,184.3
60.920000000,191.7
60.980000000,171.6
61.040000000,176.3
61.100000000,176.1
61.160000000,200.5
61.220000000,186.3
61.280000000,203.5
61.340000000,174.2
61.400000000,200.5
61.460000000,198.6
61.520000000,196.8
61.580000000,202.8
61.640000000,199.0
61.700000000,254.0
61.760000000,252.2
61.820000000,325.5
61.880000000,381.0
61.940000000,316.3
62.000000000,308.2
62.060000000,297.7
62.120000000,236.4
62.180000000,260.9
62.240000000,230.2
62.300000000,245.4
62.360000000,220.9
62.420000000,204.9
62.480000000,210.6
62.540000000,187.0
62.600000000,199.0
62.660000000,203.6
62.720000000,201.6
62.780000000,171.8
62.840000000,174.5
62.900000000,187.5
62.960000000,188.0
63.020000000,158.8
63.080000000,185.0
63.140000000,167.2
63.200000000,160.7
63.260000000,159.2
63.320000000,184.1
63.380000000,163.2
63.440000000,167.9
63.500000000,149.2
63.560000000,149.9
63.620000000,152.1
63.680000000,148.3
63.740000000,142.5
63.800000000,163.4
63.860000000,170.5
63.920000000,153.8
63.980000000,155.1
64.040000000,175.5
64.100000000,173.2
64.160000000,180.3
64.220000000,167.2
64.280000000,174.2
64.340000000,158.3
64.400000000,129.8
64.460000000,155.0
64.520000000,155.1
64.580000000,156.6
64.640000000,149.4
64.700000000,144.0
64.760000000,183.3
64.820000000,180.4
64.880000000,162.3
64.940000000,160.5
65.000000000,161.0
65.060000000,148.1
65.120000000,183.8
65.180000000,167.3
65.240000000,172.5
65.300000000,168.7
65.360000000,192.3
65.420000000,170.6
65.480000000,181.2
65.540000000,159.2
65.600000000,168.6
65.660000000,184.5
65.720000000,149.4
65.780000000,141.2
65.840000000,155.7
65.900000000,149.1
65.960000000,148.6
66.020000000,140.1
66.080000000,145.3
66.140000000,162.6
66.200000000,159.5
66.260000000,123.8
66.320000000,146.2
66.380000000,139.8
66.440000000,149.4
66.500000000,137.3
66.560000000,136.6
66.620000000,149.0
66.680000000,134.5
66.740000000,152.8
66.800000000,135.7
66.860000000,143.3
66.920000000,136.0
66.980000000,140.3
67.040000000,153.0
67.100000000,122.1
67.160000000,139.5
67.220000000,127.7
67.280000000,151.9
67.340000000,152.7
67.400000000,155.1
67.460000000,134.1
67.520000000,136.6
67.580000000,146.6
67.640000000,156.1
67.700000000,146.0
67.760000000,172.3
67.820000000,196.9
67.880000000,183.6
67.940000000,165.5
68.000000000,193.2
68.060000000,168.0
68.120000000,194.0
68.180000000,232.8
68.240000000,216.6
68.300000000,222.0
68.360000000,275.1
68.420000000,221.6
68.480000000,181.8
68.540000000,217.8
68.600000000,192.7
68.660000000,165.5
68.720000000,162.6
68.780000000,185.8
68.840000000,176.6
68.900000000,179.1
68.960000000,170.6
69.020000000,182.9
69.080000000,207.6
69.140000000,195.5
69.200000000,192.3
69.260000000,200.9
69.320000000,212.5
69.380000000,213.0
69.440000000,207.0
69.500000000,201.6
69.560000000,218.7
69.620000000,241.1
69.680000000,227.6
69.740000000,215.0
69.800000000,198.4
69.860000000,227.6
69.920000000,223.5
69.980000000,232.8
70.040000000,232.2
70.100000000,238.0
70.160000000,247.6
70.220000000,247.2
70.280000000,217.2
70.340000000,208.4
70.400000000,234.9
70.460000000,210.1
70.520000000,208.5
70.580000000,200.6
70.640000000,185.3
70.700000000,191.3
70.760000000,194.0
70.820000000,175.5
70.880000000,190.5
70.940000000,190.5
71.000000000,170.8
71.060000000,151.2
71.120000000,178.6
71.180000000,152.3
71.240000000,143.1
71.300000000,172.3
71.360000000,172.7
71.420000000,166.7
71.480000000,142.4
71.540000000,164.0
71.600000000,161.6
71.660000000,158.7
71.720000000,167.6
71.780000000,166.9
71.840000000,141.5
71.900000000,156.7
71.960000000,161.4
72.020000000,146.8
72.080000000,167.5
72.140000000,161.4
72.200000000,168.6
72.260000000,163.3
72.320000000,163.5
72.380000000,155.3
72.440000000,167.9
72.500000000,148.9
72.560000000,152.2
72.620000000,159.6
72.680000000,174.2
72.740000000,205.8
72.800000000,187.6
72.860000000,197.2
72.920000000,202.8
72.980000000,214.6
73.040000000,189.3
73.100000000,183.4
73.160000000,152.5
73.220000000,182.5
73.280000000,182.9
73.340000000,184.4
73.400000000,161.7
73.460000000,190.9
73.520000000,216.2
73.580000000,189.6
73.640000000,169.1
73.700000000,176.5
73.760000000,172.3
73.820000000,145.2
73.880000000,146.0
73.940000000,139.0
74.000000000,136.8
74.060000000,159.1
74.120000000,161.1
74.180000000,137.1
74.240000000,144.8
74.300000000,134.0
74.360000000,150.6
74.420000000,150.8
74.480000000,153.2
74.540000000,134.0
74.600000000,136.3
74.660000000,142.5
74.720000000,153.9
74.780000000,160.1
74.840000000,137.8
74.900000000,156.4
74.960000000,134.5
74.980000000,135.9