File: Datasets/Mendeley/MND_008.csv
[Measurement conditions]
Sample identification,
Comment - 1,"Configuration=Configuration General-1, Owner=User-1, Creation date=7/25/2007 1:24:35 PM"
Comment - 2,"Goniometer=PW3050/20 HR  (Theta/2Theta); Minimum step size 2Theta:0.0001; Minimum step size Omega:0.0001"
Comment - 3,"Sample stage=MRD Cradle; Minimum step size Phi:0.01; Minimum step size Psi:0.01; Minimum step size X:0.01; Minimum step size Y:0.01; Minimum step size Z:0.001"
Comment - 4,"Diffractometer system=XPERT-MPD"
Comment - 5,"Measurement program=Sara Port, Owner=SPAC, Creation date=11/17/2015 3:06:16 PM"
Anode material,Cu
K-Alpha1 wavelength,1.5405980
K-Alpha2 wavelength,1.5444260
Ratio K-Alpha2/K-Alpha1,0.500
Monochromator used,NO
File date and time,02/Feb/2017 13:19
Unit cell,
h k l, 0 0 0
Scan axis,Gonio
Scan range,15.00000,85.05000
No. of points, 7005
Scan type,CONTINUOUS
[Scan points]
Angle,Intensity
15.00500,75.0
15.05500,63.0
15.10500,36.0
15.15500,55.0
15.20500,56.0
15.25500,57.0
15.30500,65.0
15.35500,56.0
15.40500,60.0
15.45500,73.0
15.50500,74.0
15.55500,65.0
15.60500,78.0
15.65500,40.0
15.70500,72.0
15.75500,57.0
15.80500,61.0
15.85500,51.0
15.90500,71.0
15.95500,42.0
16.00500,68.0
16.05500,65.0
16.10500,53.0
16.15500,62.0
16.20500,59.0
16.25500,51.0
16.30500,51.0
16.35500,48.0
16.40500,49.0
16.45500,62.0
16.50500,47.0
16.55500,51.0
16.60500,57.0
16.65500,59.0
16.70500,50.0
16.75500,58.0
16.80500,57.0
16.85500,62.0
16.90500,75.0
16.95500,64.0
17.00500,56.0
17.05500,57.0
17.10500,57.0
17.15500,58.0
17.20500,48.0
17.25500,62.0
17.30500,82.0
17.35500,64.0
17.40500,80.0
17.45500,71.0
17.50500,77.0
17.55500,70.0
17.60500,72.0
17.65500,84.0
17.70500,82.0
17.75500,110.0
17.80500,96.0
17.85500,81.0
17.90500,77.0
17.95500,97.0
18.00500,59.0
18.05500,74.0
18.10500,76.0
18.15500,49.0
18.20500,68.0
18.25500,70.0
18.30500,70.0
18.35500,73.0
18.40500,55.0
18.45500,75.0
18.50500,64.0
18.55500,66.0
18.60500,67.0
18.65500,70.0
18.70500,72.0
18.75500,67.0
18.80500,72.0
18.85500,82.0
18.90500,65.0
18.95500,72.0
19.00500,76.0
19.05500,54.0
19.10500,86.0
19.15500,88.0
19.20500,75.0
19.25500,86.0
19.30500,80.0
19.35500,67.0
19.40500,71.0
19.45500,80.0
19.50500,80.0
19.55500,84.0
19.60500,81.0
19.65500,73.0
19.70500,75.0
19.75500,61.0
19.80500,73.0
19.85500,73.0
19.90500,85.0
19.95500,90.0
20.00500,93.0
20.05500,75.0
20.10500,76.0
20.15500,98.0
20.20500,79.0
20.25500,95.0
20.30500,68.0
20.35500,79.0
20.40500,89.0
20.45500,86.0
20.50500,86.0
20.55500,83.0
20.60500,81.0
20.65500,94.0
20.70500,89.0
20.75500,106.0
20.80500,90.0
20.85500,88.0
20.90500,76.0
20.95500,75.0
21.00500,74.0
21.05500,82.0
21.10500,82.0
21.15500,89.0
21.20500,89.0
21.25500,73.0
21.30500,85.0
21.35500,95.0
21.40500,77.0
21.45500,81.0
21.50500,86.0
21.55500,83.0
21.60500,92.0
21.65500,94.0
21.70500,78.0
21.75500,92.0
21.80500,102.0
21.85500,75.0
21.90500,78.0
21.95500,82.0
22.00500,96.0
22.05500,89.0
22.10500,97.0
22.15500,100.0
22.20500,110.0
22.25500,103.0
22.30500,91.0
22.35500,93.0
22.40500,106.0
22.45500,61.0
22.50500,80.0
22.55500,84.0
22.60500,86.0
22.65500,75.0
22.70500,76.0
22.75500,89.0
22.80500,100.0
22.85500,96.0
22.90500,98.0
22.95500,97.0
23.00500,86.0
23.05500,101.0
23.10500,74.0
23.15500,88.0
23.20500,85.0
23.25500,91.0
23.30500,79.0
23.35500,96.0
23.40500,110.0
23.45500,114.0
23.50500,107.0
23.55500,91.0
23.60500,105.0
23.65500,86.0
23.70500,91.0
23.75500,99.0
23.80500,118.0
23.85500,84.0
23.90500,88.0
23.95500,105.0
24.00500,103.0
24.05500,105.0
24.10500,99.0
24.15500,112.0
24.20500,118.0
24.25500,138.0
24.30500,128.0
24.35500,132.0
24.40500,103.0
24.45500,105.0
24.50500,115.0
24.55500,112.0
24.60500,122.0
24.65500,98.0
24.70500,112.0
24.75500,139.0
24.80500,119.0
24.85500,163.0
24.90500,122.0
24.95500,125.0
25.00500,125.0
25.05500,107.0
25.10500,98.0
25.15500,107.0
25.20500,100.0
25.25500,97.0
25.30500,98.0
25.35500,89.0
25.40500,83.0
25.45500,91.0
25.50500,82.0
25.55500,83.0
25.60500,74.0
25.65500,111.0
25.70500,80.0
25.75500,87.0
25.80500,89.0
25.85500,79.0
25.90500,89.0
25.95500,103.0
26.00500,95.0
26.05500,81.0
26.10500,85.0
26.15500,74.0
26.20500,78.0
26.25500,86.0
26.30500,87.0
26.35500,82.0
26.40500,80.0
26.45500,82.0
26.50500,95.0
26.55500,88.0
26.60500,98.0
26.65500,90.0
26.70500,80.0
26.75500,101.0
26.80500,96.0
26.85500,100.0
26.90500,89.0
26.95500,102.0
27.00500,103.0
27.05500,109.0
27.10500,110.0
27.15500,128.0
27.20500,115.0
27.25500,109.0
27.30500,95.0
27.35500,126.0
27.40500,132.0
27.45500,119.0
27.50500,90.0
27.55500,96.0
27.60500,86.0
27.65500,105.0
27.70500,90.0
27.75500,98.0
27.80500,74.0
27.85500,70.0
27.90500,94.0
27.95500,91.0
28.00500,94.0
28.05500,116.0
28.10500,115.0
28.15500,138.0
28.20500,130.0
28.25500,163.0
28.30500,178.0
28.35500,179.0
28.40500,246.0
28.45500,262.0
28.50500,268.0
28.55500,308.0
28.60500,262.0
28.65500,239.0
28.70500,234.0
28.75500,163.0
28.80500,142.0
28.85500,93.0
28.90500,92.0
28.95500,83.0
29.00500,84.0
29.05500,67.0
29.10500,89.0
29.15500,72.0
29.20500,93.0
29.25500,83.0
29.30500,84.0
29.35500,73.0
29.40500,74.0
29.45500,65.0
29.50500,84.0
29.55500,77.0
29.60500,76.0
29.65500,83.0
29.70500,79.0
29.75500,74.0
29.80500,70.0
29.85500,65.0
29.90500,85.0
29.95500,72.0
30.00500,90.0
30.05500,74.0
30.10500,66.0
30.15500,80.0
30.20500,80.0
30.25500,70.0
30.30500,75.0
30.35500,74.0
30.40500,69.0
30.45500,74.0
30.50500,78.0
30.55500,63.0
30.60500,78.0
30.65500,71.0
30.70500,57.0
30.75500,59.0
30.80500,66.0
30.85500,59.0
30.90500,76.0
30.95500,55.0
31.00500,62.0
31.05500,66.0
31.10500,70.0
31.15500,70.0
31.20500,70.0
31.25500,69.0
31.30500,87.0
31.35500,67.0
31.40500,81.0
31.45500,91.0
31.50500,93.0
31.55500,81.0
31.60500,62.0
31.65500,78.0
31.70500,99.0
31.75500,85.0
31.80500,93.0
31.85500,71.0
31.90500,70.0
31.95500,74.0
32.00500,66.0
32.05500,76.0
32.10500,72.0
32.15500,80.0
32.20500,61.0
32.25500,81.0
32.30500,72.0
32.35500,76.0
32.40500,52.0
32.45500,79.0
32.50500,62.0
32.55500,57.0
32.60500,58.0
32.65500,70.0
32.70500,77.0
32.75500,72.0
32.80500,78.0
32.85500,64.0
32.90500,68.0
32.95500,51.0
33.00500,60.0
33.05500,64.0
33.10500,56.0
33.15500,54.0
33.20500,79.0
33.25500,71.0
33.30500,71.0
33.35500,48.0
33.40500,56.0
33.45500,62.0
33.50500,47.0
33.55500,71.0
33.60500,62.0
33.65500,66.0
33.70500,59.0
33.75500,57.0
33.80500,61.0
33.85500,79.0
33.90500,54.0
33.95500,68.0
34.00500,67.0
34.05500,50.0
34.10500,51.0
34.15500,49.0
34.20500,61.0
34.25500,57.0
34.30500,70.0
34.35500,85.0
34.40500,64.0
34.45500,66.0
34.50500,77.0
34.55500,47.0
34.60500,56.0
34.65500,63.0
34.70500,52.0
34.75500,52.0
34.80500,42.0
34.85500,44.0
34.90500,57.0
34.95500,55.0
35.00500,39.0
35.05500,51.0
35.10500,47.0
35.15500,53.0
35.20500,50.0
35.25500,46.0
35.30500,69.0
35.35500,55.0
35.40500,64.0
35.45500,55.0
35.50500,58.0
35.55500,62.0
35.60500,57.0
35.65500,63.0
35.70500,50.0
35.75500,58.0
35.80500,43.0
35.85500,51.0
35.90500,43.0
35.95500,50.0
36.00500,40.0
36.05500,49.0
36.10500,41.0
36.15500,46.0
36.20500,52.0
36.25500,61.0
36.30500,55.0
36.35500,58.0
36.40500,47.0
36.45500,66.0
36.50500,48.0
36.55500,61.0
36.60500,57.0
36.65500,47.0
36.70500,49.0
36.75500,36.0
36.80500,47.0
36.85500,54.0
36.90500,57.0
36.95500,39.0
37.00500,31.0
37.05500,35.0
37.10500,41.0
37.15500,42.0
37.20500,53.0
37.25500,58.0
37.30500,47.0
37.35500,39.0
37.40500,51.0
37.45500,46.0
37.50500,40.0
37.55500,46.0
37.60500,46.0
37.65500,52.0
37.70500,43.0
37.75500,53.0
37.80500,35.0
37.85500,53.0
37.90500,38.0
37.95500,51.0
38.00500,52.0
38.05500,45.0
38.10500,52.0
38.15500,64.0
38.20500,54.0
38.25500,61.0
38.30500,70.0
38.35500,41.0
38.40500,41.0
38.45500,40.0
38.50500,46.0
38.55500,50.0
38.60500,48.0
38.65500,43.0
38.70500,50.0
38.75500,61.0
38.80500,56.0
38.85500,89.0
38.90500,73.0
38.95500,102.0
39.00500,112.0
39.05500,101.0
39.10500,95.0
39.15500,91.0
39.20500,76.0
39.25500,62.0
39.30500,52.0
39.35500,48.0
39.40500,58.0
39.45500,56.0
39.50500,70.0
39.55500,51.0
39.60500,63.0
39.65500,66.0
39.70500,77.0
39.75500,66.0
39.80500,78.0
39.85500,57.0
39.90500,67.0
39.95500,58.0
40.00500,68.0
40.05500,47.0
40.10500,51.0
40.15500,49.0
40.20500,44.0
40.25500,59.0
40.30500,59.0
40.35500,53.0
40.40500,48.0
40.45500,55.0
40.50500,52.0
40.55500,42.0
40.60500,44.0
40.65500,38.0
40.70500,50.0
40.75500,48.0
40.80500,40.0
40.85500,47.0
40.90500,44.0
40.95500,30.0
41.00500,47.0
41.05500,37.0
41.10500,47.0
41.15500,32.0
41.20500,45.0
41.25500,48.0
41.30500,43.0
41.35500,45.0
41.40500,49.0
41.45500,39.0
41.50500,46.0
41.55500,64.0
41.60500,61.0
41.65500,60.0
41.70500,53.0
41.75500,49.0
41.80500,50.0
41.85500,50.0
41.90500,50.0
41.95500,48.0
42.00500,43.0
42.05500,43.0
42.10500,54.0
42.15500,52.0
42.20500,66.0
42.25500,68.0
42.30500,75.0
42.35500,90.0
42.40500,92.0
42.45500,111.0
42.50500,137.0
42.55500,138.0
42.60500,109.0
42.65500,111.0
42.70500,96.0
42.75500,83.0
42.80500,67.0
42.85500,55.0
42.90500,51.0
42.95500,52.0
43.00500,52.0
43.05500,58.0
43.10500,37.0
43.15500,60.0
43.20500,48.0
43.25500,38.0
43.30500,42.0
43.35500,45.0
43.40500,32.0
43.45500,50.0
43.50500,53.0
43.55500,42.0
43.60500,50.0
43.65500,45.0
43.70500,41.0
43.75500,45.0
43.80500,38.0
43.85500,53.0
43.90500,46.0
43.95500,46.0
44.00500,52.0
44.05500,45.0
44.10500,42.0
44.15500,27.0
44.20500,50.0
44.25500,37.0
44.30500,51.0
44.35500,35.0
44.40500,43.0
44.45500,52.0
44.50500,33.0
44.55500,49.0
44.60500,46.0
44.65500,40.0
44.70500,30.0
44.75500,41.0
44.80500,39.0
44.85500,34.0
44.90500,40.0
44.95500,27.0
45.00500,32.0
45.05500,54.0
45.10500,52.0
45.15500,43.0
45.20500,26.0
45.25500,38.0
45.30500,47.0
45.35500,47.0
45.40500,37.0
45.45500,58.0
45.50500,54.0
45.55500,41.0
45.60500,51.0
45.65500,46.0
45.70500,35.0
45.75500,40.0
45.80500,78.0
45.85500,61.0
45.90500,54.0
45.95500,58.0
46.00500,60.0
46.05500,55.0
46.10500,41.0
46.15500,44.0
46.20500,58.0
46.25500,50.0
46.30500,67.0
46.35500,78.0
46.40500,85.0
46.45500,85.0
46.50500,67.0
46.55500,78.0
46.60500,66.0
46.65500,83.0
46.70500,75.0
46.75500,63.0
46.80500,89.0
46.85500,64.0
46.90500,80.0
46.95500,69.0
47.00500,59.0
47.05500,67.0
47.10500,66.0
47.15500,46.0
47.20500,49.0
47.25500,54.0
47.30500,61.0
47.35500,49.0
47.40500,36.0
47.45500,54.0
47.50500,52.0
47.55500,36.0
47.60500,31.0
47.65500,37.0
47.70500,44.0
47.75500,36.0
47.80500,51.0
47.85500,28.0
47.90500,39.0
47.95500,43.0
48.00500,44.0
48.05500,41.0
48.10500,38.0
48.15500,36.0
48.20500,42.0
48.25500,42.0
48.30500,37.0
48.35500,35.0
48.40500,40.0
48.45500,45.0
48.50500,34.0
48.55500,32.0
48.60500,39.0
48.65500,43.0
48.70500,48.0
48.75500,44.0
48.80500,40.0
48.85500,50.0
48.90500,44.0
48.95500,45.0
49.00500,55.0
49.05500,30.0
49.10500,53.0
49.15500,43.0
49.20500,47.0
49.25500,47.0
49.30500,55.0
49.35500,52.0
49.40500,63.0
49.45500,74.0
49.50500,83.0
49.55500,88.0
49.60500,93.0
49.65500,77.0
49.70500,84.0
49.75500,48.0
49.80500,61.0
49.85500,62.0
49.90500,41.0
49.95500,29.0
50.00500,30.0
50.05500,35.0
50.10500,34.0
50.15500,34.0
50.20500,44.0
50.25500,41.0
50.30500,29.0
50.35500,27.0
50.40500,39.0
50.45500,36.0
50.50500,34.0
50.55500,43.0
50.60500,39.0
50.65500,39.0
50.70500,37.0
50.75500,39.0
50.80500,33.0
50.85500,42.0
50.90500,42.0
50.95500,53.0
51.00500,50.0
51.05500,49.0
51.10500,54.0
51.15500,42.0
51.20500,64.0
51.25500,51.0
51.30500,39.0
51.35500,63.0
51.40500,53.0
51.45500,31.0
51.50500,41.0
51.55500,51.0
51.60500,53.0
51.65500,42.0
51.70500,48.0
51.75500,53.0
51.80500,44.0
51.85500,47.0
51.90500,62.0
51.95500,72.0
52.00500,74.0
52.05500,66.0
52.10500,91.0
52.15500,84.0
52.20500,80.0
52.25500,84.0
52.30500,60.0
52.35500,57.0
52.40500,75.0
52.45500,48.0
52.50500,56.0
52.55500,75.0
52.60500,61.0
52.65500,66.0
52.70500,48.0
52.75500,55.0
52.80500,41.0
52.85500,43.0
52.90500,44.0
52.95500,41.0
53.00500,37.0
53.05500,30.0
53.10500,29.0
53.15500,35.0
53.20500,40.0
53.25500,32.0
53.30500,23.0
53.35500,32.0
53.40500,40.0
53.45500,37.0
53.50500,38.0
53.55500,41.0
53.60500,31.0
53.65500,46.0
53.70500,31.0
53.75500,53.0
53.80500,44.0
53.85500,37.0
53.90500,38.0
53.95500,41.0
54.00500,35.0
54.05500,32.0
54.10500,45.0
54.15500,39.0
54.20500,37.0
54.25500,26.0
54.30500,31.0
54.35500,37.0
54.40500,30.0
54.45500,46.0
54.50500,38.0
54.55500,34.0
54.60500,39.0
54.65500,43.0
54.70500,43.0
54.75500,33.0
54.80500,38.0
54.85500,49.0
54.90500,38.0
54.95500,41.0
55.00500,36.0
55.05500,30.0
55.10500,36.0
55.15500,36.0
55.20500,34.0
55.25500,35.0
55.30500,33.0
55.35500,32.0
55.40500,35.0
55.45500,44.0
55.50500,45.0
55.55500,33.0
55.60500,46.0
55.65500,57.0
55.70500,45.0
55.75500,54.0
55.80500,56.0
55.85500,46.0
55.90500,39.0
55.95500,43.0
56.00500,55.0
56.05500,33.0
56.10500,54.0
56.15500,49.0
56.20500,39.0
56.25500,39.0
56.30500,38.0
56.35500,45.0
56.40500,44.0
56.45500,41.0
56.50500,25.0
56.55500,26.0
56.60500,29.0
56.65500,50.0
56.70500,49.0
56.75500,35.0
56.80500,57.0
56.85500,42.0
56.90500,54.0
56.95500,44.0
57.00500,46.0
57.05500,40.0
57.10500,36.0
57.15500,37.0
57.20500,34.0
57.25500,46.0
57.30500,59.0
57.35500,55.0
57.40500,50.0
57.45500,41.0
57.50500,39.0
57.55500,36.0
57.60500,36.0
57.65500,33.0
57.70500,43.0
57.75500,39.0
57.80500,40.0
57.85500,50.0
57.90500,33.0
57.95500,32.0
58.00500,21.0
58.05500,48.0
58.10500,40.0
58.15500,45.0
58.20500,52.0
58.25500,48.0
58.30500,50.0
58.35500,36.0
58.40500,29.0
58.45500,36.0
58.50500,49.0
58.55500,44.0
58.60500,50.0
58.65500,50.0
58.70500,53.0
58.75500,48.0
58.80500,69.0
58.85500,60.0
58.90500,59.0
58.95500,58.0
59.00500,62.0
59.05500,59.0
59.10500,66.0
59.15500,64.0
59.20500,54.0
59.25500,52.0
59.30500,60.0
59.35500,48.0
59.40500,55.0
59.45500,63.0
59.50500,48.0
59.55500,48.0
59.60500,64.0
59.65500,49.0
59.70500,40.0
59.75500,36.0
59.80500,53.0
59.85500,40.0
59.90500,42.0
59.95500,44.0
60.00500,44.0
60.05500,40.0
60.10500,37.0
60.15500,45.0
60.20500,39.0
60.25500,57.0
60.30500,32.0
60.35500,41.0
60.40500,32.0
60.45500,29.0
60.50500,49.0
60.55500,42.0
60.60500,45.0
60.65500,42.0
60.70500,53.0
60.75500,48.0
60.80500,37.0
60.85500,44.0
60.90500,30.0
60.95500,39.0
61.00500,45.0
61.05500,48.0
61.10500,38.0
61.15500,40.0
61.20500,42.0
61.25500,43.0
61.30500,43.0
61.35500,38.0
61.40500,30.0
61.45500,44.0
61.50500,25.0
61.55500,28.0
61.60500,34.0
61.65500,53.0
61.70500,40.0
61.75500,26.0
61.80500,40.0
61.85500,31.0
61.90500,47.0
61.95500,41.0
62.00500,43.0
62.05500,38.0
62.10500,38.0
62.15500,30.0
62.20500,42.0
62.25500,40.0
62.30500,42.0
62.35500,50.0
62.40500,47.0
62.45500,58.0
62.50500,42.0
62.55500,45.0
62.60500,50.0
62.65500,55.0
62.70500,58.0
62.75500,52.0
62.80500,40.0
62.85500,51.0
62.90500,35.0
62.95500,54.0
63.00500,35.0
63.05500,37.0
63.10500,54.0
63.15500,29.0
63.20500,38.0
63.25500,31.0
63.30500,42.0
63.35500,42.0
63.40500,44.0
63.45500,36.0
63.50500,54.0
63.55500,37.0
63.60500,38.0
63.65500,54.0
63.70500,37.0
63.75500,38.0
63.80500,52.0
63.85500,42.0
63.90500,49.0
63.95500,47.0
64.00500,33.0
64.05500,36.0
64.10500,44.0
64.15500,45.0
64.20500,54.0
64.25500,57.0
64.30500,56.0
64.35500,68.0
64.40500,70.0
64.45500,56.0
64.50500,48.0
64.55500,51.0
64.60500,70.0
64.65500,64.0
64.70500,49.0
64.75500,50.0
64.80500,65.0
64.85500,56.0
64.90500,52.0
64.95500,46.0
65.00500,55.0
65.05500,61.0
65.10500,63.0
65.15500,49.0
65.20500,54.0
65.25500,58.0
65.30500,51.0
65.35500,52.0
65.40500,37.0
65.45500,44.0
65.50500,38.0
65.55500,52.0
65.60500,36.0
65.65500,52.0
65.70500,47.0
65.75500,48.0
65.80500,39.0
65.85500,43.0
65.90500,53.0
65.95500,45.0
66.00500,51.0
66.05500,45.0
66.10500,46.0
66.15500,50.0
66.20500,52.0
66.25500,50.0
66.30500,47.0
66.35500,40.0
66.40500,47.0
66.45500,31.0
66.50500,46.0
66.55500,36.0
66.60500,36.0
66.65500,43.0
66.70500,29.0
66.75500,34.0
66.80500,30.0
66.85500,49.0
66.90500,47.0
66.95500,50.0
67.00500,33.0
67.05500,46.0
67.10500,29.0
67.15500,41.0
67.20500,45.0
67.25500,55.0
67.30500,50.0
67.35500,36.0
67.40500,52.0
67.45500,48.0
67.50500,55.0
67.55500,63.0
67.60500,60.0
67.65500,59.0
67.70500,60.0
67.75500,57.0
67.80500,47.0
67.85500,56.0
67.90500,48.0
67.95500,45.0
68.00500,32.0
68.05500,56.0
68.10500,45.0
68.15500,41.0
68.20500,43.0
68.25500,33.0
68.30500,52.0
68.35500,49.0
68.40500,43.0
68.45500,49.0
68.50500,55.0
68.55500,50.0
68.60500,41.0
68.65500,41.0
68.70500,51.0
68.75500,46.0
68.80500,48.0
68.85500,57.0
68.90500,39.0
68.95500,48.0
69.00500,51.0
69.05500,55.0
69.10500,51.0
69.15500,49.0
69.20500,64.0
69.25500,61.0
69.30500,76.0
69.35500,71.0
69.40500,68.0
69.45500,80.0
69.50500,74.0
69.55500,84.0
69.60500,73.0
69.65500,76.0
69.70500,68.0
69.75500,62.0
69.80500,62.0
69.85500,58.0
69.90500,47.0
69.95500,36.0
70.00500,58.0
70.05500,48.0
70.10500,31.0
70.15500,53.0
70.20500,53.0
70.25500,41.0
70.30500,39.0
70.35500,37.0
70.40500,42.0
70.45500,47.0
70.50500,35.0
70.55500,40.0
70.60500,47.0
70.65500,41.0
70.70500,32.0
70.75500,52.0
70.80500,37.0
70.85500,42.0
70.90500,42.0
70.95500,41.0
71.00500,34.0
71.05500,41.0
71.10500,50.0
71.15500,47.0
71.20500,35.0
71.25500,46.0
71.30500,49.0
71.35500,48.0
71.40500,45.0
71.45500,50.0
71.50500,32.0
71.55500,35.0
71.60500,47.0
71.65500,39.0
71.70500,35.0
71.75500,45.0
71.80500,41.0
71.85500,56.0
71.90500,57.0
71.95500,55.0
72.00500,58.0
72.05500,60.0
72.10500,53.0
72.15500,52.0
72.20500,45.0
72.25500,48.0
72.30500,46.0
72.35500,47.0
72.40500,55.0
72.45500,56.0
72.50500,62.0
72.55500,57.0
72.60500,74.0
72.65500,63.0
72.70500,52.0
72.75500,85.0
72.80500,59.0
72.85500,51.0
72.90500,61.0
72.95500,64.0
73.00500,53.0
73.05500,55.0
73.10500,54.0
73.15500,41.0
73.20500,41.0
73.25500,40.0
73.30500,50.0
73.35500,35.0
73.40500,45.0
73.45500,38.0
73.50500,39.0
73.55500,36.0
73.60500,55.0
73.65500,47.0
73.70500,45.0
73.75500,34.0
73.80500,47.0
73.85500,38.0
73.90500,44.0
73.95500,47.0
74.00500,46.0
74.05500,47.0
74.10500,41.0
74.15500,44.0
74.20500,35.0
74.25500,34.0
74.30500,42.0
74.35500,32.0
74.40500,27.0
74.45500,46.0
74.50500,49.0
74.55500,39.0
74.60500,46.0
74.65500,40.0
74.70500,26.0
74.75500,42.0
74.80500,30.0
74.85500,35.0
74.90500,37.0
74.95500,41.0
75.00500,37.0
75.05500,47.0
75.10500,41.0
75.15500,43.0
75.20500,47.0
75.25500,40.0
75.30500,43.0
75.35500,61.0
75.40500,45.0
75.45500,59.0
75.50500,62.0
75.55500,44.0
75.60500,56.0
75.65500,59.0
75.70500,62.0
75.75500,59.0
75.80500,49.0
75.85500,48.0
75.90500,50.0
75.95500,51.0
76.00500,56.0
76.05500,41.0
76.10500,44.0
76.15500,34.0
76.20500,41.0
76.25500,36.0
76.30500,45.0
76.35500,36.0
76.40500,40.0
76.45500,32.0
76.50500,40.0
76.55500,56.0
76.60500,38.0
76.65500,32.0
76.70500,42.0
76.75500,27.0
76.80500,46.0
76.85500,47.0
76.90500,37.0
76.95500,42.0
77.00500,37.0
77.05500,37.0
77.10500,40.0
77.15500,35.0
77.20500,46.0
77.25500,49.0
77.30500,48.0
77.35500,33.0
77.40500,32.0
77.45500,39.0
77.50500,53.0
77.55500,51.0
77.60500,48.0
77.65500,43.0
77.70500,43.0
77.75500,51.0
77.80500,48.0
77.85500,44.0
77.90500,49.0
77.95500,50.0
78.00500,53.0
78.05500,53.0
78.10500,60.0
78.15500,53.0
78.20500,42.0
78.25500,49.0
78.30500,61.0
78.35500,46.0
78.40500,49.0
78.45500,38.0
78.50500,48.0
78.55500,34.0
78.60500,42.0
78.65500,53.0
78.70500,52.0
78.75500,49.0
78.80500,44.0
78.85500,42.0
78.90500,52.0
78.95500,64.0
79.00500,49.0
79.05500,46.0
79.10500,53.0
79.15500,31.0
79.20500,50.0
79.25500,38.0
79.30500,30.0
79.35500,29.0
79.40500,37.0
79.45500,50.0
79.50500,40.0
79.55500,35.0
79.60500,29.0
79.65500,39.0
79.70500,36.0
79.75500,23.0
79.80500,35.0
79.85500,36.0
79.90500,37.0
79.95500,40.0
80.00500,35.0
80.05500,43.0
80.10500,38.0
80.15500,42.0
80.20500,39.0
80.25500,51.0
80.30500,31.0
80.35500,46.0
80.40500,38.0
80.45500,47.0
80.50500,39.0
80.55500,54.0
80.60500,52.0
80.65500,39.0
80.70500,49.0
80.75500,51.0
80.80500,38.0
80.85500,51.0
80.90500,38.0
80.95500,38.0
81.00500,44.0
81.05500,48.0
81.10500,47.0
81.15500,53.0
81.20500,64.0
81.25500,52.0
81.30500,38.0
81.35500,60.0
81.40500,46.0
81.45500,49.0
81.50500,26.0
81.55500,49.0
81.60500,36.0
81.65500,35.0
81.70500,43.0
81.75500,47.0
81.80500,44.0
81.85500,40.0
81.90500,34.0
81.95500,31.0
82.00500,60.0
82.05500,49.0
82.10500,40.0
82.15500,23.0
82.20500,35.0
82.25500,36.0
82.30500,47.0
82.35500,34.0
82.40500,35.0
82.45500,46.0
82.50500,35.0
82.55500,29.0
82.60500,32.0
82.65500,30.0
82.70500,42.0
82.75500,25.0
82.80500,39.0
82.85500,43.0
82.90500,31.0
82.95500,31.0
83.00500,36.0
83.05500,33.0
83.10500,40.0
83.15500,25.0
83.20500,53.0
83.25500,43.0
83.30500,26.0
83.35500,36.0
83.40500,26.0
83.45500,32.0
83.50500,45.0
83.55500,32.0
83.60500,22.0
83.65500,29.0
83.70500,33.0
83.75500,25.0
83.80500,32.0
83.85500,31.0
83.90500,27.0
83.95500,37.0
84.00500,30.0
84.05500,32.0
84.10500,43.0
84.15500,45.0
84.20500,30.0
84.25500,35.0
84.30500,42.0
84.35500,37.0
84.40500,34.0
84.45500,29.0
84.50500,47.0
84.55500,27.0
84.60500,46.0
84.65500,46.0
84.70500,35.0
84.75500,45.0
84.80500,45.0
84.85500,48.0
84.90500,43.0
84.95500,40.0
85.00500,53.0
85.04500,43.0