File: Datasets/Mendeley/MND_015.csv
#EXPORTTYPE:                 ,DATA ALL                                 ,,,
#FILE:                       ,Be-Al-Sc-Zr-VIM-1400.ngb-ds3              ,,,
#FORMAT:                     ,NETZSCH5                                 ,,,
#FTYPE:                      ,ANSI                                     ,,,
#IDENTITY:                   ,Be-Al-Sc-Zr-VIM-1400                      ,,,
#DECIMAL:                    ,POINT                                    ,,,
#SEPARATOR:                  ,COMMA                                    ,,,
#MTYPE:                      ,DSC                                      ,,,
#INSTRUMENT:                 ,NETZSCH STA 449F3                        ,,,
#PROJECT:                    ,ATF                                      ,,,
#DATE/TIME:                  ,2018/6/4 16:56:56 (UTC+8)                ,,,
#CORR. FILE:                 ,baseline-1500-10kmin 2018-5-22 .ngb-bs3,,,
#TEMPCAL:                    ,575_STA449F3_SIC_69_S_A20193_Tcal.ngb-ts3,,,
#SENSITIVITY:                ,575_STA449F3_SIC_69_S_A20193_Scal.ngb-es3,,,
#LABORATORY:                 ,ATF                                      ,,,
#OPERATOR:                   ,zy                                       ,,,
#REMARK:                     ,                                         ,,,
#SAMPLE:                     ,Be-Al-Sc-Zr-AM-1400                      ,,,
#SAMPLE MASS /mg:            ,36.4,,,
#MATERIAL:                   ,                                     ,,,
#REFERENCE:                  ,Al2O3                                    ,,,
#REFERENCE MASS /mg:         ,0,,,
#TYPE OF CRUCIBLE:           ,DSC/TG pan Al2O3                         ,,,
#SAMPLE CRUCIBLE MASS /mg:   ,0,,,
#REFERENCE CRUCIBLE MASS /mg:,0,,,
#PROTECTIVE GAS:             ,ARGON                                    ,,,
#FLOW RATE /(ml/min):        ,40,,,
#PURGE GAS 1:                ,<not defined>                            ,,,
#FLOW RATE 1:                ,                                         ,,,
#PURGE GAS 2:                ,ARGON                                    ,,,
#FLOW RATE 2 /(ml/min):      ,40,,,
#DSC RANGE /V:              ,5000,,,
#TG RANGE /mg:               ,35000,,,
#TAU-R:                      ,---                                      ,,,
#CORR. CODE:                 ,20,,,
#EXO:                        ,-1,,,
#RANGE:                      ,40/10.0(K/min)/1400C                  ,,,
#SEGMENT:                    ,S1/1                                     ,,,
#SEG. 1:                     ,40C/10.0(K/min)/1400C                  ,,,
,,,,
##Temp./C,Time/min,DSC/(mW/mg),Mass/%,Sensit./(uV/mW)
39.991,0,5.71E-05,100,1.10038
41.491,0.86354,4.40E-02,100.00489,1.09838
42.991,1.18241,8.29E-02,100.00984,1.09638
44.491,1.43466,0.11751,100.01489,1.09438
45.991,1.65383,0.14978,100.01894,1.09238
47.491,1.85179,0.17968,100.01522,1.09038
48.991,2.03458,0.20707,100.00052,1.08838
50.491,2.20646,0.23301,100.01048,1.08638
51.991,2.36936,0.25735,100.02192,1.08438
53.491,2.52487,0.28015,100.02627,1.08238
54.991,2.67491,0.30162,100.01762,1.08038
56.491,2.82092,0.32233,100.02889,1.07838
57.991,2.9629,0.34117,100.01987,1.07638
59.491,3.10153,0.35967,100.02221,1.07438
60.991,3.23744,0.37669,100.02073,1.07239
62.491,3.37067,0.39289,100.02057,1.07039
63.991,3.50194,0.40812,100.02795,1.06839
65.491,3.6321,0.42279,100.04534,1.06639
66.991,3.76081,0.4364,100.0478,1.06439
68.491,3.88805,0.44932,100.04498,1.0624
69.991,4.01442,0.46175,100.04903,1.0604
71.491,4.14017,0.47282,100.03627,1.0584
72.991,4.26533,0.48389,100.03269,1.05641
74.491,4.38996,0.49413,100.03654,1.05441
75.991,4.51405,0.50395,100.04282,1.05242
77.491,4.63764,0.51305,100.04488,1.05043
78.991,4.76088,0.52152,100.04423,1.04843
80.491,4.88381,0.52963,100.05057,1.04644
81.991,5.00643,0.53696,100.05165,1.04445
83.491,5.12884,0.54389,100.04999,1.04246
84.991,5.25123,0.55077,100.05758,1.04047
86.491,5.3737,0.55717,100.06178,1.03848
87.991,5.49616,0.56274,100.05708,1.03649
89.491,5.61851,0.56768,100.05417,1.0345
90.991,5.74095,0.57255,100.05154,1.03252
92.491,5.86355,0.57711,100.0442,1.03053
93.991,5.98647,0.58078,100.04423,1.02855
95.491,6.10967,0.58414,100.04888,1.02656
96.991,6.23324,0.5875,100.05831,1.02458
98.491,6.35698,0.59032,100.06391,1.0226
99.991,6.4813,0.59279,100.06915,1.02062
101.491,6.60637,0.59489,100.06622,1.01864
102.991,6.73194,0.59647,100.07133,1.01666
104.491,6.85821,0.59799,100.06731,1.01469
105.991,6.98529,0.59928,100.07585,1.01271
107.491,7.1132,0.60006,100.07759,1.01074
108.991,7.24177,0.60071,100.07281,1.00876
110.491,7.37106,0.60131,100.06675,1.00679
111.991,7.50151,0.60131,100.06616,1.00482
113.491,7.63272,0.6013,100.06474,1.00285
114.991,7.76449,0.60105,100.07074,1.00088
116.491,7.89696,0.60032,100.06131,0.99892
117.991,8.03008,0.60024,100.06346,0.99695
119.491,8.16438,0.59937,100.0695,0.99499
120.991,8.29957,0.59831,100.0517,0.99303
122.491,8.435,0.59731,100.05319,0.99107
123.991,8.57102,0.5965,100.05381,0.98911
125.491,8.70782,0.59532,100.0609,0.98715
126.991,8.84514,0.59402,100.06873,0.98519
128.491,8.983,0.59254,100.07059,0.98324
129.991,9.12175,0.59115,100.07539,0.98129
131.491,9.2608,0.58975,100.07433,0.97934
132.991,9.40055,0.58816,100.07173,0.97739
134.491,9.5411,0.58632,100.07193,0.97544
135.991,9.68203,0.58516,100.06794,0.9735
137.491,9.82347,0.58338,100.06587,0.97155
138.991,9.96525,0.58196,100.05628,0.96961
140.491,10.1077,0.58074,100.0543,0.96767
141.991,10.25046,0.57898,100.072,0.96573
143.491,10.39349,0.57746,100.06874,0.9638
144.991,10.53724,0.57625,100.07445,0.96186
146.491,10.68146,0.5748,100.07936,0.95993
147.991,10.82606,0.57335,100.07419,0.958
149.491,10.97107,0.5723,100.07922,0.95607
150.991,11.11627,0.57095,100.07506,0.95415
152.491,11.26212,0.56991,100.07687,0.95222
153.991,11.4085,0.5688,100.06083,0.9503
155.491,11.55543,0.5677,100.07257,0.94838
156.991,11.70246,0.56658,100.06621,0.94647
158.491,11.84965,0.56564,100.07506,0.94455
159.991,11.99748,0.56476,100.06564,0.94264
161.491,12.14538,0.56424,100.07827,0.94073
162.991,12.29354,0.56378,100.08544,0.93882
164.491,12.4421,0.56294,100.08461,0.93691
165.991,12.5909,0.56225,100.08432,0.93501
167.491,12.74003,0.5617,100.08297,0.93311
168.991,12.88981,0.56111,100.08131,0.93121
170.491,13.03967,0.56077,100.07721,0.92931
171.991,13.18929,0.56048,100.09281,0.92742
173.491,13.33929,0.56008,100.09095,0.92553
174.991,13.4898,0.56012,100.08024,0.92364
176.491,13.63979,0.5595,100.07718,0.92175
177.991,13.78983,0.55934,100.07885,0.91987
179.491,13.94021,0.55935,100.07527,0.91799
180.991,14.0907,0.55914,100.09017,0.91611
182.491,14.24108,0.55931,100.10071,0.91423
183.991,14.39126,0.55913,100.09276,0.91236
185.491,14.54155,0.55934,100.09588,0.91049
186.991,14.69171,0.5593,100.08845,0.90862
188.491,14.84175,0.5594,100.09459,0.90675
189.991,14.9922,0.55936,100.09677,0.90489
191.491,15.14253,0.5596,100.08571,0.90303
192.991,15.29279,0.55978,100.09625,0.90117
194.491,15.44322,0.55965,100.08168,0.89932
195.991,15.59353,0.55997,100.09205,0.89747
197.491,15.74393,0.55999,100.09313,0.89562
198.991,15.89417,0.5602,100.08657,0.89377
200.491,16.0445,0.56033,100.07963,0.89193
201.991,16.19513,0.56059,100.09248,0.89009
203.491,16.34599,0.56069,100.09491,0.88825
204.991,16.49657,0.56093,100.09525,0.88641
206.491,16.64708,0.56117,100.10323,0.88458
207.991,16.79788,0.56141,100.09553,0.88275
209.491,16.94864,0.5611,100.09024,0.88093
210.991,17.09914,0.56147,100.09155,0.87911
212.491,17.25003,0.56157,100.08242,0.87729
213.991,17.4009,0.5618,100.08848,0.87547
215.491,17.55182,0.56174,100.08419,0.87366
216.991,17.70292,0.56211,100.08492,0.87185
218.491,17.85351,0.56215,100.08688,0.87004
219.991,18.00424,0.56231,100.09124,0.86824
221.491,18.1552,0.56234,100.08788,0.86644
222.991,18.30589,0.56259,100.08582,0.86464
224.491,18.45676,0.56282,100.093,0.86284
225.991,18.60771,0.56316,100.0937,0.86105
227.491,18.75839,0.5634,100.08255,0.85927
228.991,18.90896,0.56379,100.09795,0.85748
230.491,19.05952,0.56404,100.09813,0.8557
231.991,19.21045,0.56417,100.09204,0.85392
233.491,19.36113,0.56431,100.10466,0.85215
234.991,19.51159,0.56445,100.10767,0.85038
236.491,19.66193,0.5649,100.09712,0.84861
237.991,19.81211,0.56508,100.09236,0.84685
239.491,19.96241,0.56539,100.08528,0.84508
240.991,20.11296,0.56554,100.08512,0.84333
242.491,20.26342,0.56589,100.09684,0.84157
243.991,20.41367,0.56583,100.10013,0.83982
245.491,20.5639,0.56613,100.10055,0.83808
246.991,20.71418,0.56627,100.10055,0.83633
248.491,20.86442,0.56646,100.08982,0.83459
249.991,21.01458,0.56648,100.09706,0.83286
251.491,21.16476,0.5668,100.10181,0.83112
252.991,21.31516,0.56681,100.09695,0.82939
254.491,21.46546,0.56686,100.10549,0.82767
255.991,21.61544,0.56697,100.1043,0.82595
257.491,21.76566,0.5672,100.09569,0.82423
258.991,21.91579,0.56703,100.09699,0.82251
260.491,22.06582,0.56699,100.0894,0.8208
261.991,22.21593,0.56694,100.10355,0.8191
263.491,22.36606,0.56713,100.10074,0.81739
264.991,22.5162,0.56736,100.10208,0.81569
266.491,22.66643,0.56719,100.10448,0.814
267.991,22.81669,0.56752,100.10951,0.8123
269.491,22.96671,0.56779,100.11215,0.81062
270.991,23.11691,0.56797,100.09905,0.80893
272.491,23.26705,0.5682,100.09845,0.80725
273.991,23.41715,0.56824,100.11618,0.80557
275.491,23.56721,0.56836,100.11291,0.8039
276.991,23.71737,0.56813,100.11998,0.80223
278.491,23.86754,0.56801,100.12478,0.80056
279.991,24.01779,0.56821,100.11941,0.7989
281.491,24.16791,0.56826,100.11628,0.79724
282.991,24.318,0.56809,100.1169,0.79559
284.491,24.46815,0.56809,100.1321,0.79394
285.991,24.61821,0.56812,100.1159,0.7923
287.491,24.7683,0.56826,100.10992,0.79065
288.991,24.91816,0.5683,100.10193,0.78902
290.491,25.06802,0.56866,100.10006,0.78738
291.991,25.21804,0.56862,100.11096,0.78575
293.491,25.36804,0.56831,100.11655,0.78412
294.991,25.51821,0.5684,100.11687,0.7825
296.491,25.6684,0.5681,100.11649,0.78088
297.991,25.81847,0.56799,100.11538,0.77927
299.491,25.96851,0.56788,100.11537,0.77766
300.991,26.11851,0.56751,100.1202,0.77606
302.491,26.26895,0.5671,100.12164,0.77445
303.991,26.41942,0.5668,100.13285,0.77286
305.491,26.56975,0.56679,100.12252,0.77126
306.991,26.72022,0.56621,100.12443,0.76967
308.491,26.87055,0.56642,100.11615,0.76809
309.991,27.02072,0.56567,100.1161,0.76651
311.491,27.17082,0.56547,100.11065,0.76493
312.991,27.32131,0.5654,100.12072,0.76336
314.491,27.47165,0.56531,100.11317,0.76179
315.991,27.6215,0.56459,100.1215,0.76022
317.491,27.77135,0.5646,100.12198,0.75866
318.991,27.92165,0.56425,100.13015,0.75711
320.491,28.07206,0.564,100.13012,0.75556
321.991,28.22221,0.56377,100.13852,0.75401
323.491,28.37236,0.56361,100.14047,0.75247
324.991,28.52281,0.56332,100.12468,0.75093
326.491,28.67302,0.563,100.12902,0.74939
327.991,28.82325,0.56263,100.13256,0.74786
329.491,28.97356,0.56264,100.13446,0.74634
330.991,29.1239,0.56189,100.12052,0.74481
332.491,29.27371,0.56173,100.12331,0.7433
333.991,29.4238,0.56171,100.12669,0.74178
335.491,29.57401,0.56168,100.1348,0.74027
336.991,29.72438,0.56099,100.14535,0.73877
338.491,29.87465,0.561,100.13433,0.73727
339.991,30.02485,0.56068,100.13944,0.73577
341.491,30.17516,0.56027,100.13033,0.73428
342.991,30.32538,0.56045,100.13214,0.7328
344.491,30.47591,0.55993,100.12676,0.73131
345.991,30.62654,0.55954,100.13139,0.72984
347.491,30.77698,0.55904,100.13214,0.72836
348.991,30.92732,0.55864,100.12455,0.72689
350.491,31.07755,0.55827,100.1377,0.72543
351.991,31.2278,0.55804,100.13488,0.72397
353.491,31.37815,0.55761,100.13849,0.72251
354.991,31.52855,0.5574,100.13802,0.72106
356.491,31.67893,0.55715,100.12722,0.71961
357.991,31.82931,0.55715,100.13735,0.71817
359.491,31.97974,0.55701,100.13378,0.71673
360.991,32.12991,0.55669,100.13242,0.7153
362.491,32.28027,0.55615,100.13791,0.71387
363.991,32.43074,0.55599,100.13816,0.71244
365.491,32.58104,0.55544,100.14795,0.71102
366.991,32.73136,0.5552,100.14897,0.70961
368.491,32.88183,0.55491,100.13828,0.7082
369.991,33.03218,0.55463,100.14745,0.70679
371.491,33.18253,0.5544,100.14532,0.70539
372.991,33.33327,0.55397,100.13128,0.70399
374.491,33.48374,0.55371,100.14442,0.7026
375.991,33.63395,0.55313,100.1436,0.70121
377.491,33.78445,0.55324,100.1464,0.69982
378.991,33.93478,0.55298,100.14617,0.69844
380.491,34.08487,0.55254,100.1502,0.69707
381.991,34.23502,0.55212,100.14031,0.6957
383.491,34.38561,0.55199,100.12473,0.69433
384.991,34.53618,0.55168,100.13553,0.69297
386.491,34.68617,0.55144,100.14461,0.69161
387.991,34.83638,0.55131,100.14583,0.69026
389.491,34.98699,0.55083,100.14774,0.68891
390.991,35.13725,0.55022,100.13916,0.68757
392.491,35.28752,0.54985,100.14571,0.68623
393.991,35.43798,0.54956,100.15053,0.6849
395.491,35.58816,0.54903,100.15211,0.68357
396.991,35.73853,0.54883,100.15476,0.68224
398.491,35.88875,0.54888,100.15474,0.68092
399.991,36.0387,0.54844,100.15917,0.67961
401.491,36.18898,0.54789,100.15069,0.6783
402.991,36.33926,0.54755,100.16048,0.67699
404.491,36.4895,0.5472,100.15164,0.67569
405.991,36.63994,0.5466,100.14836,0.67439
407.491,36.79052,0.54642,100.1519,0.6731
408.991,36.94088,0.54565,100.15117,0.67181
410.491,37.09121,0.54502,100.14943,0.67053
411.991,37.2415,0.54475,100.15137,0.66925
413.491,37.39165,0.54421,100.15371,0.66798
414.991,37.54181,0.54429,100.15387,0.66671
416.491,37.69192,0.54407,100.15288,0.66544
417.991,37.84187,0.54354,100.15045,0.66418
419.491,37.99175,0.5429,100.16045,0.66293
420.991,38.14175,0.54254,100.16228,0.66167
422.491,38.29204,0.54212,100.15649,0.66043
423.991,38.44219,0.54173,100.14588,0.65919
425.491,38.59241,0.54135,100.15615,0.65795
426.991,38.74254,0.5406,100.15924,0.65672
428.491,38.89268,0.54013,100.15649,0.65549
429.991,39.04292,0.5397,100.15412,0.65427
431.491,39.19331,0.53933,100.15462,0.65305
432.991,39.34392,0.53881,100.16069,0.65183
434.491,39.49393,0.53802,100.16665,0.65062
435.991,39.6437,0.53777,100.1628,0.64942
437.491,39.7939,0.53726,100.16664,0.64822
438.991,39.94383,0.53784,100.17322,0.64702
440.491,40.09392,0.53702,100.1644,0.64583
441.991,40.24385,0.53613,100.14729,0.64465
443.491,40.39389,0.53612,100.15506,0.64347
444.991,40.54404,0.53567,100.16368,0.64229
446.491,40.69383,0.53506,100.15997,0.64112
447.991,40.84389,0.53476,100.1618,0.63995
449.491,40.99405,0.53431,100.15743,0.63879
450.991,41.14418,0.5336,100.15907,0.63763
452.491,41.29425,0.53283,100.1646,0.63647
453.991,41.44438,0.53223,100.16077,0.63532
455.491,41.59439,0.53131,100.17339,0.63418
456.991,41.74436,0.53094,100.17329,0.63304
458.491,41.89468,0.53035,100.17557,0.6319
459.991,42.04502,0.52925,100.15989,0.63077
461.491,42.19535,0.52838,100.16388,0.62965
462.991,42.34545,0.52767,100.16341,0.62852
464.491,42.496,0.52706,100.15987,0.62741
465.991,42.64641,0.5261,100.17772,0.6263
467.491,42.79643,0.52562,100.16717,0.62519
468.991,42.94655,0.52504,100.16081,0.62408
470.491,43.09671,0.52415,100.16043,0.62299
471.991,43.247,0.52364,100.1596,0.62189
473.491,43.39735,0.52271,100.17706,0.6208
474.991,43.54756,0.5218,100.18276,0.61972
476.491,43.69771,0.52121,100.17118,0.61864
477.991,43.84773,0.52067,100.17385,0.61756
479.491,43.99793,0.52023,100.16268,0.61649
480.991,44.14816,0.51937,100.17258,0.61542
482.491,44.29837,0.51874,100.18355,0.61436
483.991,44.44852,0.51797,100.1862,0.6133
485.491,44.59901,0.51712,100.19237,0.61225
486.991,44.74915,0.51612,100.18891,0.6112
488.491,44.89893,0.51556,100.18504,0.61016
489.991,45.04902,0.51454,100.18646,0.60912
491.491,45.19908,0.51431,100.1892,0.60808
492.991,45.34891,0.51326,100.18016,0.60705
494.491,45.49886,0.51291,100.18727,0.60602
495.991,45.64901,0.51234,100.19153,0.605
497.491,45.79925,0.51158,100.18307,0.60399
498.991,45.9493,0.51069,100.18438,0.60297
500.491,46.09952,0.51017,100.18437,0.60197
501.991,46.24992,0.50938,100.18187,0.60096
503.491,46.40004,0.5081,100.18517,0.59996
504.991,46.55054,0.50715,100.18193,0.59897
506.491,46.70108,0.50554,100.18578,0.59798
507.991,46.85116,0.50509,100.19375,0.59699
509.491,47.00152,0.50423,100.18757,0.59601
510.991,47.15192,0.50382,100.17894,0.59503
512.491,47.30189,0.50334,100.18856,0.59406
513.991,47.45211,0.50263,100.18913,0.59309
515.491,47.60234,0.50238,100.20557,0.59213
516.991,47.7525,0.50198,100.18848,0.59117
518.491,47.90231,0.50125,100.19386,0.59022
519.991,48.05228,0.50103,100.20707,0.58926
521.491,48.20222,0.50066,100.20356,0.58832
522.991,48.35218,0.49984,100.18721,0.58738
524.491,48.50231,0.49853,100.19633,0.58644
525.991,48.65225,0.49779,100.18924,0.58551
527.491,48.80216,0.49685,100.18732,0.58458
528.991,48.95238,0.49608,100.18797,0.58365
530.491,49.10268,0.49508,100.19156,0.58273
531.991,49.2527,0.49463,100.18672,0.58182
533.491,49.40283,0.49341,100.1818,0.58091
534.991,49.55287,0.49299,100.18797,0.58
536.491,49.70299,0.49188,100.1828,0.5791
537.991,49.85319,0.49082,100.19224,0.5782
539.491,50.00379,0.49048,100.18245,0.5773
540.991,50.1542,0.48961,100.19331,0.57641
542.491,50.3043,0.48881,100.19333,0.57553
543.991,50.45429,0.48865,100.18739,0.57465
545.491,50.60448,0.48812,100.18434,0.57377
546.991,50.7546,0.48725,100.18805,0.5729
548.491,50.90478,0.48693,100.19927,0.57203
549.991,51.05488,0.48589,100.18969,0.57116
551.491,51.20511,0.48582,100.18258,0.5703
552.991,51.35516,0.48508,100.19208,0.56945
554.491,51.50518,0.48478,100.18192,0.5686
555.991,51.65538,0.48407,100.18621,0.56775
557.491,51.80571,0.48369,100.20121,0.56691
558.991,51.956,0.48256,100.1907,0.56607
560.491,52.10597,0.48225,100.18757,0.56523
561.991,52.25575,0.48164,100.18081,0.5644
563.491,52.40582,0.48063,100.18524,0.56357
564.991,52.55582,0.48056,100.20072,0.56275
566.491,52.70578,0.47962,100.19665,0.56193
567.991,52.85574,0.47936,100.19389,0.56112
569.491,53.00575,0.47891,100.18222,0.56031
570.991,53.15581,0.47788,100.18392,0.5595
572.491,53.30589,0.4766,100.19365,0.5587
573.991,53.45582,0.47556,100.19052,0.5579
575.491,53.60575,0.47493,100.19713,0.5571
576.991,53.75574,0.47369,100.19922,0.55631
578.491,53.90532,0.47269,100.19293,0.55553
579.991,54.05504,0.47202,100.19961,0.55475
581.491,54.20481,0.47069,100.20305,0.55397
582.991,54.35435,0.47021,100.2031,0.55319
584.491,54.50408,0.46904,100.19396,0.55242
585.991,54.65398,0.46806,100.1873,0.55166
587.491,54.80413,0.46696,100.19227,0.55089
588.991,54.95408,0.46614,100.19036,0.55014
590.491,55.10433,0.4647,100.19259,0.54938
591.991,55.25474,0.46421,100.1925,0.54863
593.491,55.40489,0.46281,100.2074,0.54788
594.991,55.55495,0.46152,100.20811,0.54714
596.491,55.705,0.46063,100.21044,0.5464
597.991,55.85514,0.45987,100.20237,0.54567
599.491,56.0053,0.4585,100.20991,0.54493
600.991,56.15528,0.45796,100.20638,0.54421
602.491,56.30532,0.4567,100.21225,0.54348
603.991,56.45537,0.45579,100.20484,0.54276
605.491,56.60541,0.4548,100.20251,0.54205
606.991,56.75577,0.45433,100.20336,0.54134
608.491,56.90571,0.45366,100.19763,0.54063
609.991,57.05557,0.45268,100.20417,0.53992
611.491,57.20554,0.45225,100.21664,0.53922
612.991,57.35532,0.45139,100.20661,0.53852
614.491,57.50515,0.44997,100.22227,0.53783
615.991,57.65495,0.44889,100.21498,0.53714
617.491,57.80488,0.44742,100.21306,0.53645
618.991,57.95481,0.44634,100.22831,0.53577
620.491,58.1046,0.44479,100.21665,0.53509
621.991,58.25448,0.44381,100.21626,0.53442
623.491,58.40438,0.44334,100.21107,0.53374
624.991,58.55422,0.4424,100.22064,0.53308
626.491,58.70394,0.44192,100.22235,0.53241
627.991,58.85368,0.44119,100.22017,0.53175
629.491,59.00346,0.44065,100.22008,0.53109
630.991,59.15334,0.4401,100.23799,0.53044
632.491,59.30318,0.43959,100.22822,0.52979
633.991,59.4532,0.43879,100.2335,0.52914
635.491,59.60349,0.43779,100.23178,0.5285
636.991,59.75363,0.43716,100.21967,0.52786
638.491,59.90343,0.43593,100.22801,0.52722
639.991,60.05344,0.43485,100.21991,0.52659
641.491,60.20345,0.43487,100.21542,0.52596
642.991,60.35374,0.45401,100.22761,0.52534
644.491,60.50445,0.53182,100.21779,0.52471
645.991,60.65575,0.66107,100.23545,0.5241
647.491,60.80793,0.78192,100.21298,0.52348
648.991,60.96049,0.90318,100.23987,0.52287
650.491,61.1133,1.0398,100.23556,0.52226
651.991,61.26629,1.19538,100.23649,0.52165
653.491,61.41944,1.37638,100.23678,0.52105
654.991,61.57303,1.58299,100.23769,0.52045
656.491,61.72697,1.80824,100.24001,0.51986
657.991,61.88082,2.04765,100.23655,0.51926
659.491,62.03325,2.14286,100.22826,0.51868
660.991,62.18184,1.8001,100.23493,0.51809
662.491,62.32663,1.45988,100.24574,0.51751
663.991,62.46965,1.19267,100.24563,0.51693
665.491,62.61266,0.99042,100.24248,0.51635
666.991,62.75622,0.8398,100.23693,0.51578
668.491,62.90063,0.72513,100.23815,0.51521
669.991,63.04639,0.64016,100.23919,0.51464
671.491,63.19365,0.57542,100.24264,0.51408
672.991,63.34233,0.52627,100.24398,0.51352
674.491,63.49175,0.48874,100.24945,0.51296
675.991,63.64163,0.46161,100.23242,0.51241
677.491,63.79195,0.44113,100.23614,0.51186
678.991,63.94293,0.4256,100.24273,0.51131
680.491,64.09417,0.41328,100.23493,0.51077
681.991,64.24523,0.40384,100.25167,0.51022
683.491,64.39645,0.39667,100.24037,0.50968
684.991,64.54768,0.39122,100.25714,0.50915
686.491,64.69874,0.38744,100.25839,0.50862
687.991,64.84962,0.38463,100.26238,0.50809
689.491,65.00018,0.38256,100.24753,0.50756
690.991,65.15094,0.38041,100.2442,0.50704
692.491,65.30141,0.37943,100.25204,0.50652
693.991,65.45179,0.37839,100.26296,0.506
695.491,65.6019,0.37769,100.26038,0.50548
696.991,65.75192,0.37698,100.25225,0.50497
698.491,65.90191,0.37639,100.246,0.50446
699.991,66.05196,0.37562,100.25187,0.50395
701.491,66.20205,0.37537,100.26097,0.50345
702.991,66.35217,0.37494,100.25711,0.50295
704.491,66.50224,0.37305,100.26828,0.50245
705.991,66.65212,0.37266,100.26026,0.50196
707.491,66.80233,0.3719,100.26504,0.50146
708.991,66.95258,0.3712,100.2618,0.50097
710.491,67.10253,0.36983,100.25533,0.50049
711.991,67.25255,0.3694,100.26427,0.5
713.491,67.40258,0.3695,100.2726,0.49952
714.991,67.55253,0.36889,100.26937,0.49904
716.491,67.7023,0.36738,100.26604,0.49857
717.991,67.85227,0.36623,100.28254,0.49809
719.491,68.0023,0.36583,100.27158,0.49762
720.991,68.15229,0.36534,100.26885,0.49715
722.491,68.30219,0.36426,100.28935,0.49669
723.991,68.45201,0.36372,100.27958,0.49622
725.491,68.60188,0.36273,100.26976,0.49576
726.991,68.75182,0.36147,100.28301,0.4953
728.491,68.90181,0.36092,100.28084,0.49485
729.991,69.05148,0.36083,100.27553,0.49439
731.491,69.20138,0.35905,100.27235,0.49394
732.991,69.35116,0.35881,100.27743,0.4935
734.491,69.50073,0.35833,100.27017,0.49305
735.991,69.65029,0.3577,100.28435,0.49261
737.491,69.79977,0.35718,100.27744,0.49217
738.991,69.94939,0.35628,100.27941,0.49173
740.491,70.09926,0.35602,100.2797,0.49129
741.991,70.24896,0.35437,100.28134,0.49086
743.491,70.39865,0.353,100.28316,0.49043
744.991,70.54885,0.35198,100.26666,0.49
746.491,70.69908,0.35066,100.28362,0.48957
747.991,70.84937,0.34958,100.29754,0.48915
749.491,70.99964,0.34761,100.28213,0.48872
750.991,71.14982,0.34636,100.29916,0.4883
752.491,71.29989,0.34497,100.29177,0.48789
753.991,71.44996,0.34385,100.28517,0.48747
755.491,71.60031,0.34276,100.28951,0.48706
756.991,71.75077,0.34079,100.28766,0.48665
758.491,71.90126,0.33958,100.28353,0.48624
759.991,72.05131,0.33932,100.29362,0.48583
761.491,72.20129,0.3389,100.27902,0.48543
762.991,72.35139,0.33708,100.28797,0.48502
764.491,72.50134,0.3356,100.29573,0.48462
765.991,72.65125,0.33409,100.2943,0.48423
767.491,72.80128,0.3334,100.29788,0.48383
768.991,72.95091,0.33236,100.29905,0.48344
770.491,73.10051,0.33129,100.31231,0.48304
771.991,73.25016,0.33004,100.29313,0.48265
773.491,73.39987,0.32939,100.27499,0.48227
774.991,73.54988,0.32783,100.28543,0.48188
776.491,73.69969,0.3267,100.30248,0.4815
777.991,73.84963,0.32534,100.30658,0.48111
779.491,73.99966,0.32437,100.31184,0.48073
780.991,74.14951,0.32142,100.30274,0.48036
782.491,74.29941,0.32049,100.3027,0.47998
783.991,74.44951,0.32012,100.30053,0.47961
785.491,74.59959,0.31795,100.30743,0.47923
786.991,74.74965,0.3175,100.31568,0.47886
788.491,74.89991,0.31618,100.2981,0.47849
789.991,75.04992,0.31493,100.3184,0.47813
791.491,75.19995,0.31407,100.31484,0.47776
792.991,75.35022,0.31194,100.32251,0.4774
794.491,75.50046,0.31091,100.30437,0.47704
795.991,75.65067,0.30865,100.2956,0.47668
797.491,75.80099,0.30658,100.3055,0.47632
798.991,75.95136,0.30551,100.31584,0.47596
800.491,76.10161,0.30381,100.31698,0.47561
801.991,76.2515,0.30297,100.3215,0.47525
803.491,76.40162,0.30095,100.31947,0.4749
804.991,76.55162,0.30012,100.31852,0.47455
806.491,76.70139,0.29909,100.33459,0.4742
807.991,76.85105,0.29759,100.3187,0.47386
809.491,77.00087,0.29594,100.32069,0.47351
810.991,77.15081,0.29434,100.3167,0.47317
812.491,77.30086,0.29211,100.30398,0.47283
813.991,77.45115,0.29033,100.30125,0.47249
815.491,77.6015,0.28872,100.29815,0.47215
816.991,77.75195,0.28778,100.32693,0.47181
818.491,77.9021,0.28647,100.33188,0.47148
819.991,78.05218,0.28553,100.33206,0.47114
821.491,78.20224,0.28444,100.33698,0.47081
822.991,78.3521,0.28367,100.33644,0.47048
824.491,78.50199,0.28289,100.30744,0.47015
825.991,78.6521,0.28188,100.33418,0.46982
827.491,78.80223,0.27947,100.32883,0.46949
828.991,78.9521,0.27836,100.33314,0.46917
830.491,79.10196,0.27743,100.33622,0.46884
831.991,79.25181,0.27634,100.35122,0.46852
833.491,79.40155,0.27563,100.3423,0.4682
834.991,79.55139,0.27492,100.33166,0.46788
836.491,79.70107,0.2743,100.33687,0.46756
837.991,79.85054,0.27208,100.34506,0.46724
839.491,80.00029,0.27193,100.33543,0.46692
840.991,80.14991,0.27176,100.34065,0.46661
842.491,80.29933,0.26938,100.35285,0.46629
843.991,80.44913,0.26867,100.36802,0.46598
845.491,80.59923,0.26741,100.36717,0.46567
846.991,80.74906,0.26635,100.34651,0.46536
848.491,80.89862,0.26544,100.35902,0.46505
849.991,81.04819,0.2647,100.34783,0.46474
851.491,81.19773,0.26312,100.35025,0.46443
852.991,81.34739,0.26214,100.3534,0.46413
854.491,81.49723,0.261,100.36025,0.46382
855.991,81.64719,0.25962,100.34631,0.46352
857.491,81.79712,0.25716,100.36568,0.46321
858.991,81.94679,0.25606,100.36405,0.46291
860.491,82.0967,0.25504,100.36325,0.46261
861.991,82.24666,0.25375,100.36206,0.46231
863.491,82.39647,0.2521,100.36481,0.46201
864.991,82.54621,0.25107,100.35127,0.46171
866.491,82.69578,0.25037,100.36517,0.46142
867.991,82.84559,0.24988,100.35695,0.46112
869.491,82.99557,0.24837,100.34729,0.46083
870.991,83.1453,0.24694,100.35099,0.46053
872.491,83.29502,0.24628,100.36449,0.46024
873.991,83.44454,0.24482,100.37102,0.45995
875.491,83.59406,0.24429,100.38341,0.45966
876.991,83.74408,0.24169,100.38889,0.45936
878.491,83.894,0.24064,100.38406,0.45908
879.991,84.0437,0.23993,100.39036,0.45879
881.491,84.19362,0.23833,100.37737,0.4585
882.991,84.3434,0.2368,100.36386,0.45821
884.491,84.49307,0.23458,100.37582,0.45792
885.991,84.64284,0.23365,100.3851,0.45764
887.491,84.79285,0.23218,100.38597,0.45735
888.991,84.94295,0.23082,100.40211,0.45707
890.491,85.09305,0.2301,100.40758,0.45678
891.991,85.24297,0.2301,100.38177,0.4565
893.491,85.3927,0.22969,100.39248,0.45622
894.991,85.54225,0.22953,100.39534,0.45594
896.491,85.69173,0.22818,100.3725,0.45566
897.991,85.84128,0.22797,100.39993,0.45538
899.491,85.99106,0.22654,100.38978,0.4551
900.991,86.1409,0.22525,100.38107,0.45482
902.491,86.29064,0.22409,100.36935,0.45454
903.991,86.44032,0.22156,100.39431,0.45426
905.491,86.59051,0.22026,100.3931,0.45398
906.991,86.74069,0.21882,100.38131,0.45371
908.491,86.89055,0.2177,100.38762,0.45343
909.991,87.04053,0.21681,100.4083,0.45315
911.491,87.19051,0.21548,100.40296,0.45288
912.991,87.3406,0.21394,100.39665,0.4526
914.491,87.4907,0.21168,100.40149,0.45233
915.991,87.64072,0.20947,100.39915,0.45205
917.491,87.79053,0.20878,100.39726,0.45178
918.991,87.94035,0.20616,100.41454,0.45151
920.491,88.09039,0.20526,100.41973,0.45123
921.991,88.24007,0.20427,100.40632,0.45096
923.491,88.38974,0.20338,100.414,0.45069
924.991,88.53953,0.20206,100.3962,0.45042
926.491,88.68929,0.20097,100.41258,0.45015
927.991,88.83878,0.19959,100.41009,0.44988
929.491,88.98839,0.19885,100.41339,0.44961
930.991,89.13785,0.19838,100.4069,0.44934
932.491,89.28752,0.19672,100.40701,0.44907
933.991,89.43746,0.19573,100.40966,0.4488
935.491,89.58735,0.19451,100.40829,0.44853
936.991,89.73755,0.19308,100.40831,0.44826
938.491,89.88777,0.19179,100.41302,0.44799
939.991,90.03786,0.19063,100.43015,0.44772
941.491,90.18801,0.18938,100.43813,0.44745
942.991,90.33795,0.18872,100.42235,0.44718
944.491,90.48792,0.18715,100.43636,0.44691
945.991,90.63781,0.18583,100.41363,0.44665
947.491,90.78758,0.18488,100.41726,0.44638
948.991,90.93767,0.18338,100.41433,0.44611
950.491,91.08783,0.18168,100.43059,0.44584
951.991,91.23788,0.18083,100.42889,0.44557
953.491,91.38777,0.17993,100.41952,0.44531
954.991,91.53744,0.17887,100.43071,0.44504
956.491,91.68738,0.17672,100.43604,0.44477
957.991,91.83769,0.17583,100.43475,0.4445
959.491,91.98772,0.17562,100.43717,0.44424
960.991,92.13752,0.17416,100.43093,0.44397
962.491,92.28766,0.17209,100.44115,0.4437
963.991,92.43755,0.17141,100.45001,0.44344
965.491,92.58745,0.1696,100.45484,0.44317
966.991,92.73754,0.16838,100.4418,0.4429
968.491,92.88745,0.1672,100.44091,0.44263
969.991,93.03733,0.16548,100.4509,0.44237
971.491,93.18725,0.16508,100.44554,0.4421
972.991,93.33702,0.16352,100.43277,0.44183
974.491,93.48665,0.16179,100.44249,0.44156
975.991,93.6364,0.16093,100.45826,0.4413
977.491,93.78638,0.15888,100.45427,0.44103
978.991,93.93644,0.15804,100.46191,0.44076
980.491,94.08657,0.15589,100.47113,0.44049
981.991,94.23638,0.15502,100.46616,0.44023
983.491,94.38617,0.15369,100.46434,0.43996
984.991,94.53611,0.15167,100.47901,0.43969
986.491,94.68619,0.15038,100.47509,0.43942
987.991,94.83596,0.14942,100.47646,0.43915
989.491,94.98572,0.14823,100.47124,0.43888
990.991,95.13564,0.14682,100.47303,0.43861
992.491,95.28516,0.14562,100.4747,0.43834
993.991,95.43467,0.14503,100.49005,0.43807
995.491,95.58429,0.14419,100.48086,0.4378
996.991,95.73373,0.14257,100.50175,0.43753
998.491,95.88311,0.14227,100.48773,0.43726
999.991,96.03239,0.14118,100.48733,0.43699
1001.491,96.18186,0.13983,100.47776,0.43672
1002.991,96.33131,0.13786,100.48116,0.43645
1004.491,96.48075,0.13715,100.47886,0.43618
1005.991,96.63051,0.13591,100.47941,0.43591
1007.491,96.78032,0.13456,100.48985,0.43564
1008.991,96.93014,0.13264,100.48132,0.43536
1010.491,97.08039,0.12982,100.51241,0.43509
1011.991,97.23078,0.12808,100.49902,0.43482
1013.491,97.38091,0.12709,100.48858,0.43454
1014.991,97.53101,0.12557,100.49594,0.43427
1016.491,97.68098,0.12402,100.49714,0.43399
1017.991,97.83087,0.12307,100.50582,0.43372
1019.491,97.98087,0.12202,100.48956,0.43344
1020.991,98.13074,0.12145,100.49469,0.43317
1022.491,98.28025,0.12505,100.50361,0.43289
1023.991,98.43013,0.12335,100.49891,0.43261
1025.491,98.58007,0.1212,100.50605,0.43234
1026.991,98.72989,0.12041,100.51401,0.43206
1028.491,98.88008,0.11888,100.51759,0.43178
1029.991,99.02997,0.1177,100.51236,0.4315
1031.491,99.18006,0.1168,100.53022,0.43122
1032.991,99.33018,0.11644,100.51699,0.43094
1034.491,99.48013,0.11651,100.51018,0.43066
1035.991,99.63016,0.11596,100.52279,0.43038
1037.491,99.78049,0.11598,100.53068,0.4301
1038.991,99.93072,0.11525,100.52656,0.42982
1040.491,100.08084,0.11495,100.53633,0.42954
1041.991,100.23087,0.11458,100.53665,0.42925
1043.491,100.38099,0.11432,100.52703,0.42897
1044.991,100.53109,0.11384,100.53343,0.42869
1046.491,100.6813,0.11387,100.52928,0.4284
1047.991,100.83155,0.11363,100.52847,0.42812
1049.491,100.98168,0.11348,100.52512,0.42783
1050.991,101.13187,0.11265,100.5327,0.42754
1052.491,101.28209,0.11183,100.54799,0.42725
1053.991,101.43224,0.11147,100.54078,0.42697
1055.491,101.5824,0.11105,100.53077,0.42668
1056.991,101.73261,0.11077,100.54767,0.42639
1058.491,101.88268,0.11061,100.54696,0.4261
1059.991,102.0323,0.11155,100.56161,0.42581
1061.491,102.18192,0.11142,100.54366,0.42552
1062.991,102.33152,0.11174,100.55453,0.42522
1064.491,102.48113,0.11217,100.55378,0.42493
1065.991,102.63095,0.11246,100.53843,0.42464
1067.491,102.781,0.11217,100.56059,0.42434
1068.991,102.9315,0.11329,100.55565,0.42405
1070.491,103.08177,0.11397,100.56238,0.42375
1071.991,103.23167,0.11225,100.5463,0.42346
1073.491,103.38168,0.1142,100.55688,0.42316
1074.991,103.53148,0.1154,100.55865,0.42286
1076.491,103.68114,0.11629,100.5669,0.42256
1077.991,103.83108,0.11934,100.56507,0.42226
1079.491,103.9809,0.1223,100.57194,0.42196
1080.991,104.13079,0.12448,100.55917,0.42166
1082.491,104.28076,0.12676,100.56207,0.42136
1083.991,104.43087,0.12941,100.57119,0.42106
1085.491,104.58091,0.13166,100.57402,0.42075
1086.991,104.73096,0.13341,100.56453,0.42045
1088.491,104.88111,0.13644,100.57075,0.42014
1089.991,105.03144,0.13791,100.5662,0.41984
1091.491,105.18163,0.14008,100.56517,0.41953
1092.991,105.33179,0.14232,100.58625,0.41922
1094.491,105.48192,0.14483,100.58682,0.41891
1095.991,105.63199,0.14835,100.58515,0.41861
1097.491,105.78214,0.14998,100.58211,0.41829
1098.991,105.93206,0.15234,100.59081,0.41798
1100.491,106.08199,0.15564,100.59337,0.41767
1101.991,106.23225,0.15914,100.60484,0.41736
1103.491,106.38219,0.16418,100.61041,0.41704
1104.991,106.53213,0.16785,100.60836,0.41673
1106.491,106.68221,0.17295,100.5995,0.41641
1107.991,106.83228,0.17769,100.59187,0.4161
1109.491,106.98226,0.18203,100.60464,0.41578
1110.991,107.13221,0.1853,100.58973,0.41546
1112.491,107.28203,0.1893,100.5794,0.41514
1113.991,107.43163,0.19353,100.58726,0.41482
1115.491,107.58128,0.19888,100.62149,0.4145
1116.991,107.73085,0.20442,100.60917,0.41418
1118.491,107.88045,0.21007,100.61899,0.41385
1119.991,108.0301,0.21739,100.61428,0.41353
1121.491,108.17987,0.22435,100.61567,0.4132
1122.991,108.32975,0.23295,100.61839,0.41288
1124.491,108.47976,0.24253,100.63574,0.41255
1125.991,108.62998,0.25321,100.62527,0.41222
1127.491,108.78035,0.26495,100.62213,0.41189
1128.991,108.93063,0.27781,100.61873,0.41156
1130.491,109.08097,0.29201,100.61715,0.41123
1131.991,109.23108,0.30774,100.61883,0.4109
1133.491,109.38122,0.32562,100.64072,0.41057
1134.991,109.5312,0.34597,100.64444,0.41023
1136.491,109.68117,0.37039,100.64887,0.4099
1137.991,109.83107,0.39639,100.6418,0.40956
1139.491,109.98071,0.42644,100.64375,0.40922
1140.991,110.1306,0.45911,100.63968,0.40889
1142.491,110.28045,0.49483,100.65813,0.40855
1143.991,110.43052,0.53503,100.65286,0.40821
1145.491,110.58072,0.58001,100.6426,0.40786
1146.991,110.73093,0.6305,100.65923,0.40752
1148.491,110.88126,0.68712,100.6691,0.40718
1149.991,111.03143,0.74909,100.66085,0.40683
1151.491,111.18156,0.81715,100.65972,0.40649
1152.991,111.33159,0.89193,100.67025,0.40614
1154.491,111.48185,0.97269,100.6724,0.40579
1155.991,111.63195,1.0599,100.66485,0.40544
1157.491,111.78173,1.15224,100.67558,0.40509
1158.991,111.93154,1.25117,100.67781,0.40474
1160.491,112.08171,1.35375,100.67965,0.40439
1161.991,112.23174,1.45796,100.67309,0.40404
1163.491,112.38196,1.56202,100.68227,0.40368
1164.991,112.53218,1.6646,100.66792,0.40333
1166.491,112.68244,1.76552,100.68411,0.40297
1167.991,112.83294,1.86231,100.67689,0.40261
1169.491,112.98338,1.95242,100.67988,0.40225
1170.991,113.13367,2.03427,100.66975,0.40189
1172.491,113.28363,2.10759,100.68555,0.40153
1173.991,113.43336,2.17037,100.68225,0.40117
1175.491,113.58295,2.22454,100.69323,0.40081
1176.991,113.73233,2.26713,100.71263,0.40044
1178.491,113.88148,2.2988,100.72475,0.40008
1179.991,114.03055,2.31515,100.71251,0.39971
1181.491,114.17941,2.31178,100.70157,0.39934
1182.991,114.32801,2.25925,100.70368,0.39897
1184.491,114.47612,2.05048,100.70886,0.3986
1185.991,114.62334,1.66908,100.70089,0.39823
1187.491,114.77005,1.23306,100.71676,0.39786
1188.991,114.91694,0.81979,100.71454,0.39749
1190.491,115.06487,0.4842,100.69213,0.39711
1191.991,115.21442,0.23451,100.70241,0.39674
1193.491,115.36504,7.35E-02,100.70957,0.39636
1194.991,115.5166,-1.94E-02,100.7296,0.39598
1196.491,115.66866,-7.17E-02,100.72594,0.3956
1197.991,115.82042,-9.99E-02,100.74458,0.39522
1199.491,115.97182,-0.11682,100.74436,0.39484
1200.991,116.12284,-0.12895,100.74691,0.39446
1202.491,116.2737,-0.138,100.7621,0.39407
1203.991,116.42406,-0.14432,100.75115,0.39369
1205.491,116.57425,-0.15055,100.74055,0.3933
1206.991,116.72409,-0.15623,100.73524,0.39291
1208.491,116.87389,-0.16137,100.73219,0.39252
1209.991,117.02368,-0.16752,100.73921,0.39213
1211.491,117.17354,-0.1733,100.77551,0.39174
1212.991,117.32374,-0.17792,100.76008,0.39135
1214.491,117.47397,-0.18275,100.75275,0.39096
1215.991,117.62396,-0.18771,100.74927,0.39056
1217.491,117.77406,-0.19224,100.76571,0.39017
1218.991,117.92439,-0.19817,100.76844,0.38977
1220.491,118.0742,-0.20323,100.77424,0.38937
1221.991,118.22385,-0.20894,100.77189,0.38897
1223.491,118.37353,-0.2127,100.77336,0.38857
1224.991,118.5235,-0.21863,100.77874,0.38817
1226.491,118.67348,-0.22371,100.77228,0.38777
1227.991,118.82363,-0.22912,100.75924,0.38736
1229.491,118.97379,-0.23429,100.77534,0.38696
1230.991,119.12407,-0.23938,100.77721,0.38655
1232.491,119.2742,-0.24083,100.78692,0.38614
1233.991,119.42434,-0.24809,100.79231,0.38573
1235.491,119.5744,-0.25434,100.79155,0.38532
1236.991,119.72437,-0.26023,100.77187,0.38491
1238.491,119.87416,-0.26552,100.77459,0.3845
1239.991,120.02354,-0.27062,100.76522,0.38409
1241.491,120.17304,-0.27549,100.77069,0.38367
1242.991,120.32291,-0.28007,100.79403,0.38326
1244.491,120.47255,-0.28558,100.79757,0.38284
1245.991,120.62218,-0.29217,100.79548,0.38242
1247.491,120.77186,-0.29664,100.80893,0.382
1248.991,120.92177,-0.30187,100.81228,0.38158
1250.491,121.07208,-0.30697,100.80481,0.38116
1251.991,121.22227,-0.31186,100.79054,0.38073
1253.491,121.37236,-0.31611,100.79823,0.38031
1254.991,121.52251,-0.32065,100.80244,0.37988
1256.491,121.67276,-0.3253,100.82837,0.37946
1257.991,121.82291,-0.32822,100.82292,0.37903
1259.491,121.97316,-0.33224,100.83138,0.3786
1260.991,122.1233,-0.33541,100.82914,0.37817
1262.491,122.27329,-0.33976,100.82805,0.37774
1263.991,122.42327,-0.34225,100.81695,0.37731
1265.491,122.57304,-0.34722,100.81762,0.37687
1266.991,122.72255,-0.3516,100.8143,0.37644
1268.491,122.87219,-0.35593,100.82232,0.376
1269.991,123.02177,-0.35933,100.82166,0.37556
1271.491,123.17151,-0.36469,100.83586,0.37513
1272.991,123.32121,-0.37113,100.8273,0.37469
1274.491,123.47086,-0.37435,100.83263,0.37425
1275.991,123.62051,-0.37826,100.8542,0.3738
1277.491,123.77043,-0.3818,100.85551,0.37336
1278.991,123.92045,-0.38496,100.84372,0.37292
1280.491,124.0705,-0.38897,100.84674,0.37247
1281.991,124.22019,-0.39196,100.8451,0.37202
1283.491,124.37006,-0.39491,100.86703,0.37158
1284.991,124.52,-0.39652,100.86429,0.37113
1286.491,124.66988,-0.39813,100.85687,0.37068
1287.991,124.8197,-0.4006,100.85902,0.37022
1289.491,124.96978,-0.40369,100.87226,0.36977
1290.991,125.11994,-0.40555,100.87005,0.36932
1292.491,125.26989,-0.40742,100.8703,0.36886
1293.991,125.4201,-0.4098,100.88186,0.36841
1295.491,125.57061,-0.41119,100.87666,0.36795
1296.991,125.72078,-0.41414,100.88015,0.36749
1298.491,125.87067,-0.41588,100.89838,0.36703
1299.991,126.02092,-0.4184,100.89669,0.36657
1301.491,126.17112,-0.42035,100.89386,0.36611
1302.991,126.32116,-0.4242,100.88479,0.36565
1304.491,126.47109,-0.42685,100.90302,0.36518
1305.991,126.62067,-0.42784,100.90013,0.36472
1307.491,126.77031,-0.43002,100.88458,0.36425
1308.991,126.91999,-0.43149,100.88984,0.36378
1310.491,127.06973,-0.43348,100.89755,0.36331
1311.991,127.2196,-0.43492,100.91974,0.36284
1313.491,127.3696,-0.43785,100.90913,0.36237
1314.991,127.51969,-0.44058,100.88818,0.3619
1316.491,127.66981,-0.44242,100.88573,0.36143
1317.991,127.8198,-0.44329,100.8961,0.36095
1319.491,127.96968,-0.44473,100.92579,0.36048
1320.991,128.1198,-0.4461,100.92414,0.36
1322.491,128.2699,-0.44727,100.9187,0.35952
1323.991,128.41987,-0.44822,100.91866,0.35905
1325.491,128.56982,-0.4494,100.91482,0.35857
1326.991,128.71983,-0.44884,100.93358,0.35808
1328.491,128.86967,-0.44804,100.92775,0.3576
1329.991,129.01936,-0.44951,100.94743,0.35712
1331.491,129.16945,-0.44848,100.94567,0.35664
1332.991,129.31946,-0.45051,100.93792,0.35615
1334.491,129.46916,-0.45197,100.92802,0.35566
1335.991,129.61891,-0.45108,100.93252,0.35518
1337.491,129.76863,-0.44977,100.94469,0.35469
1338.991,129.9184,-0.44801,100.93305,0.3542
1340.491,130.06806,-0.44693,100.93739,0.35371
1341.991,130.21799,-0.44837,100.94121,0.35322
1343.491,130.36807,-0.44469,100.97319,0.35272
1344.991,130.51809,-0.44552,100.95608,0.35223
1346.491,130.66808,-0.44536,100.9668,0.35173
1347.991,130.81808,-0.44543,100.96411,0.35124
1349.491,130.9678,-0.44508,100.96888,0.35074
1350.991,131.11765,-0.4434,100.9747,0.35024
1352.491,131.26744,-0.44135,100.98099,0.34974
1353.991,131.41738,-0.4398,100.98171,0.34924
1355.491,131.56721,-0.43762,100.984,0.34874
1356.991,131.71722,-0.43749,100.98474,0.34824
1358.491,131.86724,-0.43717,100.99513,0.34774
1359.991,132.01712,-0.43757,100.98869,0.34723
1361.491,132.16689,-0.43683,101.00386,0.34673
1362.991,132.31687,-0.43328,100.99355,0.34622
1364.491,132.46719,-0.43122,100.99638,0.34571
1365.991,132.61743,-0.42867,101.00308,0.3452
1367.491,132.76758,-0.42651,101.00386,0.3447
1368.991,132.91763,-0.42824,100.98533,0.34419
1370.491,133.06744,-0.42669,101.02053,0.34367
1371.991,133.21704,-0.42774,101.02419,0.34316
1373.491,133.36665,-0.4274,101.00804,0.34265
1374.991,133.51645,-0.42711,101.01285,0.34213
1376.491,133.66612,-0.42826,101.01103,0.34162
1377.991,133.81577,-0.43041,101.02613,0.3411
1379.491,133.96566,-0.42713,101.00305,0.34058
1380.991,134.11591,-0.42879,101.01837,0.34007
1382.491,134.26633,-0.43002,101.01313,0.33955
1383.991,134.4167,-0.43078,101.00531,0.33903
1385.491,134.56688,-0.42982,101.0419,0.33851
1386.991,134.71692,-0.43253,101.02396,0.33798
1388.491,134.86684,-0.43667,101.04124,0.33746
1389.991,135.01646,-0.43814,101.05178,0.33694
1391.491,135.16603,-0.43786,101.05247,0.33641
1392.991,135.31567,-0.43859,101.06061,0.33589
1394.491,135.46557,-0.44236,101.06651,0.33536
1395.991,135.61564,-0.44045,101.06418,0.33483
1397.491,135.76566,-0.44146,101.06054,0.3343
1398.991,135.91578,-0.44329,101.06628,0.33377
1399.491,135.96569,-0.44528,101.07023,0.3336